Workbook

Sheet Schedule
P1: Schedule Conflicts: | S1: =countifs(Students!AG3:AG88,">0") -> 0 | U1: % 9-12 done: | X1: =rounddown(sum(Students!AF:AF)/(rounddown(countifs(Students!C3:C88,"<>"&""),0)*8),2) -> 1 | Y1: Over 24 students: | AB1: =countifs(R3:R88,">24")+countifs(U3:U88,">24")+countifs(X3:X88,">24")+countifs(AA3:AA88,">24")+countifs(AD3:AD88,">24")+countifs(AG3:AG88,">24")+countifs(AJ3:AJ88,">24")+countifs(AM3:AM88,">24") -> 9 | AD1: ERRORS (Ghost classes): | AG1: =iferror(sum('Ghost Classes'!E:E),0) -> 0 | AH1: Groups over for Teacher | AJ1: =sum('Teachers and Groups'!G2:G88) -> 0 | AP1: # in Each Grade
A2: Grade Level | B2: Block | C2: Day A | D2: Day B | E2: Day C | F2: Day D | G2: Day E | J2: {=if(ROW(J2:J88)=2,"Students #",if($L2:$L88="","",R2:R88+U2:U88+X2:X88+AA2:AA88+AD2:AD88+AG2:AG88+AJ2:AJ88+AM2:AM88))} -> Students # | K2: Semester | L2: Teacher | M2: Room | N2: {=if(ROW(N2:N88)=2,"Preps #",if($L2:$L88="","",countifs('Teachers and Groups'!C2:C88,L2:L88)))} -> Preps # | O2: # Hours | P2: 1 | Q2: S | R2: {=if(ROW(R2:R88)=2,"#",if(P2:P88="","",if($K2:$K88="S1",countifs('Students (Vertical)'!$D:$D,P2:P88,'Students (Vertical)'!$E:$E,P$2&"a"),if($K2:$K88="S2",countifs('Students (Vertical)'!$D:$D,P2:P88,'Students (Vertical)'!$E:$E,P$2&"b"),countifs('Students (Vertical)'!$D:$D,P2:P88,'Students (Vertical)'!$E:$E,P$2)+countifs('Students (Vertical)'!$D:$D,P2:P88,'Students (Vertical)'!$E:$E,P$2&"a")+countifs('Students (Vertical)'!$D:$D,P2:P88,'Students (Vertical)'!$E:$E,P$2&"b")))))} -> # | S2: 2 | T2: S | U2: {=if(ROW(U2:U88)=2,"#",if(S2:S88="","",if($K2:$K88="S1",countifs('Students (Vertical)'!$D:$D,S2:S88,'Students (Vertical)'!$E:$E,S$2&"a"),if($K2:$K88="S2",countifs('Students (Vertical)'!$D:$D,S2:S88,'Students (Vertical)'!$E:$E,S$2&"b"),countifs('Students (Vertical)'!$D:$D,S2:S88,'Students (Vertical)'!$E:$E,S$2)+countifs('Students (Vertical)'!$D:$D,S2:S88,'Students (Vertical)'!$E:$E,S$2&"a")+countifs('Students (Vertical)'!$D:$D,S2:S88,'Students (Vertical)'!$E:$E,S$2&"b")))))} -> # | V2: 3 | W2: S | X2: {=if(ROW(X2:X88)=2,"#",if(V2:V88="","",if($K2:$K88="S1",countifs('Students (Vertical)'!$D:$D,V2:V88,'Students (Vertical)'!$E:$E,V$2&"a"),if($K2:$K88="S2",countifs('Students (Vertical)'!$D:$D,V2:V88,'Students (Vertical)'!$E:$E,V$2&"b"),countifs('Students (Vertical)'!$D:$D,V2:V88,'Students (Vertical)'!$E:$E,V$2)+countifs('Students (Vertical)'!$D:$D,V2:V88,'Students (Vertical)'!$E:$E,V$2&"a")+countifs('Students (Vertical)'!$D:$D,V2:V88,'Students (Vertical)'!$E:$E,V$2&"b")))))} -> # | Y2: 4 | Z2: S | AA2: {=if(ROW(AA2:AA88)=2,"#",if(Y2:Y88="","",if($K2:$K88="S1",countifs('Students (Vertical)'!$D:$D,Y2:Y88,'Students (Vertical)'!$E:$E,Y$2&"a"),if($K2:$K88="S2",countifs('Students (Vertical)'!$D:$D,Y2:Y88,'Students (Vertical)'!$E:$E,Y$2&"b"),countifs('Students (Vertical)'!$D:$D,Y2:Y88,'Students (Vertical)'!$E:$E,Y$2)+countifs('Students (Vertical)'!$D:$D,Y2:Y88,'Students (Vertical)'!$E:$E,Y$2&"a")+countifs('Students (Vertical)'!$D:$D,Y2:Y88,'Students (Vertical)'!$E:$E,Y$2&"b")))))} -> # | AB2: 5 | AC2: S | AD2: {=if(ROW(AD2:AD88)=2,"#",if(AB2:AB88="","",if($K2:$K88="S1",countifs('Students (Vertical)'!$D:$D,AB2:AB88,'Students (Vertical)'!$E:$E,AB$2&"a"),if($K2:$K88="S2",countifs('Students (Vertical)'!$D:$D,AB2:AB88,'Students (Vertical)'!$E:$E,AB$2&"b"),countifs('Students (Vertical)'!$D:$D,AB2:AB88,'Students (Vertical)'!$E:$E,AB$2)+countifs('Students (Vertical)'!$D:$D,AB2:AB88,'Students (Vertical)'!$E:$E,AB$2&"a")+countifs('Students (Vertical)'!$D:$D,AB2:AB88,'Students (Vertical)'!$E:$E,AB$2&"b")))))} -> # | AE2: 6 | AF2: S | AG2: {=if(ROW(AG2:AG88)=2,"#",if(AE2:AE88="","",if($K2:$K88="S1",countifs('Students (Vertical)'!$D:$D,AE2:AE88,'Students (Vertical)'!$E:$E,AE$2&"a"),if($K2:$K88="S2",countifs('Students (Vertical)'!$D:$D,AE2:AE88,'Students (Vertical)'!$E:$E,AE$2&"b"),countifs('Students (Vertical)'!$D:$D,AE2:AE88,'Students (Vertical)'!$E:$E,AE$2)+countifs('Students (Vertical)'!$D:$D,AE2:AE88,'Students (Vertical)'!$E:$E,AE$2&"a")+countifs('Students (Vertical)'!$D:$D,AE2:AE88,'Students (Vertical)'!$E:$E,AE$2&"b")))))} -> # | AH2: 7 | AI2: S | AJ2: {=if(ROW(AJ2:AJ88)=2,"#",if(AH2:AH88="","",if($K2:$K88="S1",countifs('Students (Vertical)'!$D:$D,AH2:AH88,'Students (Vertical)'!$E:$E,AH$2&"a"),if($K2:$K88="S2",countifs('Students (Vertical)'!$D:$D,AH2:AH88,'Students (Vertical)'!$E:$E,AH$2&"b"),countifs('Students (Vertical)'!$D:$D,AH2:AH88,'Students (Vertical)'!$E:$E,AH$2)+countifs('Students (Vertical)'!$D:$D,AH2:AH88,'Students (Vertical)'!$E:$E,AH$2&"a")+countifs('Students (Vertical)'!$D:$D,AH2:AH88,'Students (Vertical)'!$E:$E,AH$2&"b")))))} -> # | AK2: 8 | AL2: S | AM2: {=if(ROW(AM2:AM88)=2,"#",if(AK2:AK88="","",if($K2:$K88="S1",countifs('Students (Vertical)'!$D:$D,AK2:AK88,'Students (Vertical)'!$E:$E,AK$2&"a"),if($K2:$K88="S2",countifs('Students (Vertical)'!$D:$D,AK2:AK88,'Students (Vertical)'!$E:$E,AK$2&"b"),countifs('Students (Vertical)'!$D:$D,AK2:AK88,'Students (Vertical)'!$E:$E,AK$2)+countifs('Students (Vertical)'!$D:$D,AK2:AK88,'Students (Vertical)'!$E:$E,AK$2&"a")+countifs('Students (Vertical)'!$D:$D,AK2:AK88,'Students (Vertical)'!$E:$E,AK$2&"b")))))} -> # | AN2: Preps | AO2: Students | AP2: 9 | AQ2: 10 | AR2: 11 | AS2: 12
A3: All | B3: 1 | C3: 1 | D3: 6 | E3: 3 | F3: 8 | G3: 5 | J3: 144 | L3: Jorge Mario Angel | N3: 2 | O3: =IFERROR(__xludf.DUMMYFUNCTION("3*counta((transpose(filter(P3:AM3,P3:AM3<>"""",isnumber(P3:AM3)=false))))"),18.0) -> 18 | S3: Band Level II | T3: 1 | U3: 27 | V3: Band Level I | W3: 1 | X3: 24 | Y3: Band Level I | Z3: 2 | AA3: 20 | AE3: Band Level II | AF3: 2 | AG3: 27 | AH3: Band Level I | AI3: 3 | AJ3: 24 | AK3: Band Level I | AL3: 4 | AM3: 22 | AO3: =if(L3="","",R3+U3+X3+AA3+AD3+AG3+AJ3+AM3) -> 144 | AP3: =if($L3="","",countifs(Students!$D:$D,$P3,Students!$E:$E,$P$2&if($K3="S1","a",if($K3="S2","b","")),Students!$A:$A,AP$2)+countifs(Students!$F:$F,$P3,Students!$G:$G,$P$2&if($K3="S1","a",if($K3="S2","b","")),Students!$A:$A,AP$2)+countifs(Students!$H:$H,$P3,Students!$I:$I,$P$2&if($K3="S1","a",if($K3="S2","b","")),Students!$A:$A,AP$2)+countifs(Students!$J:$J,$P3,Students!$K:$K,$P$2&if($K3="S1","a",if($K3="S2","b","")),Students!$A:$A,AP$2)+countifs(Students!$L:$L,$P3,Students!$M:$M,$P$2&if($K3="S1","a",if($K3="S2","b","")),Students!$A:$A,AP$2)+countifs(Students!$N:$N,$P3,Students!$O:$O,$P$2&if($K3="S1","a",if($K3="S2","b","")),Students!$A:$A,AP$2)+countifs(Students!$P:$P,$P3,Students!$Q:$Q,$P$2&if($K3="S1","a",if($K3="S2","b","")),Students!$A:$A,AP$2)+countifs(Students!$R:$R,$P3,Students!$S:$S,$P$2&if($K3="S1","a",if($K3="S2","b","")),Students!$A:$A,AP$2)+countifs(Students!$T:$T,$P3,Students!$U:$U,$P$2&if($K3="S1","a",if($K3="S2","b","")),Students!$A:$A,AP$2)+countifs(Students!$V:$V,$P3,Students!$W:$W,$P$2&if($K3="S1","a",if($K3="S2","b","")),Students!$A:$A,AP$2)+ countifs(Students!$D:$D,$S3,Students!$E:$E,$S$2&if($K3="S1","a",if($K3="S2","b","")),Students!$A:$A,AP$2)+countifs(Students!$F:$F,$S3,Students!$G:$G,$S$2&if($K3="S1","a",if($K3="S2","b","")),Students!$A:$A,AP$2)+countifs(Students!$H:$H,$S3,Students!$I:$I,$S$2&if($K3="S1","a",if($K3="S2","b","")),Students!$A:$A,AP$2)+countifs(Students!$J:$J,$S3,Students!$K:$K,$S$2&if($K3="S1","a",if($K3="S2","b","")),Students!$A:$A,AP$2)+countifs(Students!$L:$L,$S3,Students!$M:$M,$S$2&if($K3="S1","a",if($K3="S2","b","")),Students!$A:$A,AP$2)+countifs(Students!$N:$N,$S3,Students!$O:$O,$S$2&if($K3="S1","a",if($K3="S2","b","")),Students!$A:$A,AP$2)+countifs(Students!$P:$P,$S3,Students!$Q:$Q,$S$2&if($K3="S1","a",if($K3="S2","b","")),Students!$A:$A,AP$2)+countifs(Students!$R:$R,$S3,Students!$S:$S,$S$2&if($K3="S1","a",if($K3="S2","b","")),Students!$A:$A,AP$2)+countifs(Students!$T:$T,$S3,Students!$U:$U,$S$2&if($K3="S1","a",if($K3="S2","b","")),Students!$A:$A,AP$2)+countifs(Students!$V:$V,$S3,Students!$W:$W,$S$2&if($K3="S1","a",if($K3="S2","b","")),Students!$A:$A,AP$2)+ countifs(Students!$D:$D,$V3,Students!$E:$E,$V$2&if($K3="S1","a",if($K3="S2","b","")),Students!$A:$A,AP$2)+countifs(Students!$F:$F,$V3,Students!$G:$G,$V$2&if($K3="S1","a",if($K3="S2","b","")),Students!$A:$A,AP$2)+countifs(Students!$H:$H,$V3,Students!$I:$I,$V$2&if($K3="S1","a",if($K3="S2","b","")),Students!$A:$A,AP$2)+countifs(Students!$J:$J,$V3,Students!$K:$K,$V$2&if($K3="S1","a",if($K3="S2","b","")),Students!$A:$A,AP$2)+countifs(Students!$L:$L,$V3,Students!$M:$M,$V$2&if($K3="S1","a",if($K3="S2","b","")),Students!$A:$A,AP$2)+countifs(Students!$N:$N,$V3,Students!$O:$O,$V$2&if($K3="S1","a",if($K3="S2","b","")),Students!$A:$A,AP$2)+countifs(Students!$P:$P,$V3,Students!$Q:$Q,$V$2&if($K3="S1","a",if($K3="S2","b","")),Students!$A:$A,AP$2)+countifs(Students!$R:$R,$V3,Students!$S:$S,$V$2&if($K3="S1","a",if($K3="S2","b","")),Students!$A:$A,AP$2)+countifs(Students!$T:$T,$V3,Students!$U:$U,$V$2&if($K3="S1","a",if($K3="S2","b","")),Students!$A:$A,AP$2)+countifs(Students!$V:$V,$V3,Students!$W:$W,$V$2&if($K3="S1","a",if($K3="S2","b","")),Students!$A:$A,AP$2)+ countifs(Students!$D:$D,$Y3,Students!$E:$E,$Y$2&if($K3="S1","a",if($K3="S2","b","")),Students!$A:$A,AP$2)+countifs(Students!$F:$F,$Y3,Students!$G:$G,$Y$2&if($K3="S1","a",if($K3="S2","b","")),Students!$A:$A,AP$2)+countifs(Students!$H:$H,$Y3,Students!$I:$I,$Y$2&if($K3="S1","a",if($K3="S2","b","")),Students!$A:$A,AP$2)+countifs(Students!$J:$J,$Y3,Students!$K:$K,$Y$2&if($K3="S1","a",if($K3="S2","b","")),Students!$A:$A,AP$2)+countifs(Students!$L:$L,$Y3,Students!$M:$M,$Y$2&if($K3="S1","a",if($K3="S2","b","")),Students!$A:$A,AP$2)+countifs(Students!$N:$N,$Y3,Students!$O:$O,$Y$2&if($K3="S1","a",if($K3="S2","b","")),Students!$A:$A,AP$2)+countifs(Students!$P:$P,$Y3,Students!$Q:$Q,$Y$2&if($K3="S1","a",if($K3="S2","b","")),Students!$A:$A,AP$2)+countifs(Students!$R:$R,$Y3,Students!$S:$S,$Y$2&if($K3="S1","a",if($K3="S2","b","")),Students!$A:$A,AP$2)+countifs(Students!$T:$T,$Y3,Students!$U:$U,$Y$2&if($K3="S1","a",if($K3="S2","b","")),Students!$A:$A,AP$2)+countifs(Students!$V:$V,$Y3,Students!$W:$W,$Y$2&if($K3="S1","a",if($K3="S2","b","")),Students!$A:$A,AP$2)+ countifs(Students!$D:$D,$AB3,Students!$E:$E,$AB$2&if($K3="S1","a",if($K3="S2","b","")),Students!$A:$A,AP$2)+countifs(Students!$F:$F,$AB3,Students!$G:$G,$AB$2&if($K3="S1","a",if($K3="S2","b","")),Students!$A:$A,AP$2)+countifs(Students!$H:$H,$AB3,Students!$I:$I,$AB$2&if($K3="S1","a",if($K3="S2","b","")),Students!$A:$A,AP$2)+countifs(Students!$J:$J,$AB3,Students!$K:$K,$AB$2&if($K3="S1","a",if($K3="S2","b","")),Students!$A:$A,AP$2)+countifs(Students!$L:$L,$AB3,Students!$M:$M,$AB$2&if($K3="S1","a",if($K3="S2","b","")),Students!$A:$A,AP$2)+countifs(Students!$N:$N,$AB3,Students!$O:$O,$AB$2&if($K3="S1","a",if($K3="S2","b","")),Students!$A:$A,AP$2)+countifs(Students!$P:$P,$AB3,Students!$Q:$Q,$AB$2&if($K3="S1","a",if($K3="S2","b","")),Students!$A:$A,AP$2)+countifs(Students!$R:$R,$AB3,Students!$S:$S,$AB$2&if($K3="S1","a",if($K3="S2","b","")),Students!$A:$A,AP$2)+countifs(Students!$T:$T,$AB3,Students!$U:$U,$AB$2&if($K3="S1","a",if($K3="S2","b","")),Students!$A:$A,AP$2)+countifs(Students!$V:$V,$AB3,Students!$W:$W,$AB$2&if($K3="S1","a",if($K3="S2","b","")),Students!$A:$A,AP$2)+ countifs(Students!$D:$D,$AE3,Students!$E:$E,$AE$2&if($K3="S1","a",if($K3="S2","b","")),Students!$A:$A,AP$2)+countifs(Students!$F:$F,$AE3,Students!$G:$G,$AE$2&if($K3="S1","a",if($K3="S2","b","")),Students!$A:$A,AP$2)+countifs(Students!$H:$H,$AE3,Students!$I:$I,$AE$2&if($K3="S1","a",if($K3="S2","b","")),Students!$A:$A,AP$2)+countifs(Students!$J:$J,$AE3,Students!$K:$K,$AE$2&if($K3="S1","a",if($K3="S2","b","")),Students!$A:$A,AP$2)+countifs(Students!$L:$L,$AE3,Students!$M:$M,$AE$2&if($K3="S1","a",if($K3="S2","b","")),Students!$A:$A,AP$2)+countifs(Students!$N:$N,$AE3,Students!$O:$O,$AE$2&if($K3="S1","a",if($K3="S2","b","")),Students!$A:$A,AP$2)+countifs(Students!$P:$P,$AE3,Students!$Q:$Q,$AE$2&if($K3="S1","a",if($K3="S2","b","")),Students!$A:$A,AP$2)+countifs(Students!$R:$R,$AE3,Students!$S:$S,$AE$2&if($K3="S1","a",if($K3="S2","b","")),Students!$A:$A,AP$2)+countifs(Students!$T:$T,$AE3,Students!$U:$U,$AE$2&if($K3="S1","a",if($K3="S2","b","")),Students!$A:$A,AP$2)+countifs(Students!$V:$V,$AE3,Students!$W:$W,$AE$2&if($K3="S1","a",if($K3="S2","b","")),Students!$A:$A,AP$2)+ countifs(Students!$D:$D,$AH3,Students!$E:$E,$AH$2&if($K3="S1","a",if($K3="S2","b","")),Students!$A:$A,AP$2)+countifs(Students!$F:$F,$AH3,Students!$G:$G,$AH$2&if($K3="S1","a",if($K3="S2","b","")),Students!$A:$A,AP$2)+countifs(Students!$H:$H,$AH3,Students!$I:$I,$AH$2&if($K3="S1","a",if($K3="S2","b","")),Students!$A:$A,AP$2)+countifs(Students!$J:$J,$AH3,Students!$K:$K,$AH$2&if($K3="S1","a",if($K3="S2","b","")),Students!$A:$A,AP$2)+countifs(Students!$L:$L,$AH3,Students!$M:$M,$AH$2&if($K3="S1","a",if($K3="S2","b","")),Students!$A:$A,AP$2)+countifs(Students!$N:$N,$AH3,Students!$O:$O,$AH$2&if($K3="S1","a",if($K3="S2","b","")),Students!$A:$A,AP$2)+countifs(Students!$P:$P,$AH3,Students!$Q:$Q,$AH$2&if($K3="S1","a",if($K3="S2","b","")),Students!$A:$A,AP$2)+countifs(Students!$R:$R,$AH3,Students!$S:$S,$AH$2&if($K3="S1","a",if($K3="S2","b","")),Students!$A:$A,AP$2)+countifs(Students!$T:$T,$AH3,Students!$U:$U,$AH$2&if($K3="S1","a",if($K3="S2","b","")),Students!$A:$A,AP$2)+countifs(Students!$V:$V,$AH3,Students!$W:$W,$AH$2&if($K3="S1","a",if($K3="S2","b","")),Students!$A:$A,AP$2)+ countifs(Students!$D:$D,$AK3,Students!$E:$E,$AK$2&if($K3="S1","a",if($K3="S2","b","")),Students!$A:$A,AP$2)+countifs(Students!$F:$F,$AK3,Students!$G:$G,$AK$2&if($K3="S1","a",if($K3="S2","b","")),Students!$A:$A,AP$2)+countifs(Students!$H:$H,$AK3,Students!$I:$I,$AK$2&if($K3="S1","a",if($K3="S2","b","")),Students!$A:$A,AP$2)+countifs(Students!$J:$J,$AK3,Students!$K:$K,$AK$2&if($K3="S1","a",if($K3="S2","b","")),Students!$A:$A,AP$2)+countifs(Students!$L:$L,$AK3,Students!$M:$M,$AK$2&if($K3="S1","a",if($K3="S2","b","")),Students!$A:$A,AP$2)+countifs(Students!$N:$N,$AK3,Students!$O:$O,$AK$2&if($K3="S1","a",if($K3="S2","b","")),Students!$A:$A,AP$2)+countifs(Students!$P:$P,$AK3,Students!$Q:$Q,$AK$2&if($K3="S1","a",if($K3="S2","b","")),Students!$A:$A,AP$2)+countifs(Students!$R:$R,$AK3,Students!$S:$S,$AK$2&if($K3="S1","a",if($K3="S2","b","")),Students!$A:$A,AP$2)+countifs(Students!$T:$T,$AK3,Students!$U:$U,$AK$2&if($K3="S1","a",if($K3="S2","b","")),Students!$A:$A,AP$2)+countifs(Students!$V:$V,$AK3,Students!$W:$W,$AK$2&if($K3="S1","a",if($K3="S2","b","")),Students!$A:$A,AP$2)) -> 47 | AQ3: =if($L3="","",countifs(Students!$D:$D,$P3,Students!$E:$E,$P$2&if($K3="S1","a",if($K3="S2","b","")),Students!$A:$A,AQ$2)+countifs(Students!$F:$F,$P3,Students!$G:$G,$P$2&if($K3="S1","a",if($K3="S2","b","")),Students!$A:$A,AQ$2)+countifs(Students!$H:$H,$P3,Students!$I:$I,$P$2&if($K3="S1","a",if($K3="S2","b","")),Students!$A:$A,AQ$2)+countifs(Students!$J:$J,$P3,Students!$K:$K,$P$2&if($K3="S1","a",if($K3="S2","b","")),Students!$A:$A,AQ$2)+countifs(Students!$L:$L,$P3,Students!$M:$M,$P$2&if($K3="S1","a",if($K3="S2","b","")),Students!$A:$A,AQ$2)+countifs(Students!$N:$N,$P3,Students!$O:$O,$P$2&if($K3="S1","a",if($K3="S2","b","")),Students!$A:$A,AQ$2)+countifs(Students!$P:$P,$P3,Students!$Q:$Q,$P$2&if($K3="S1","a",if($K3="S2","b","")),Students!$A:$A,AQ$2)+countifs(Students!$R:$R,$P3,Students!$S:$S,$P$2&if($K3="S1","a",if($K3="S2","b","")),Students!$A:$A,AQ$2)+countifs(Students!$T:$T,$P3,Students!$U:$U,$P$2&if($K3="S1","a",if($K3="S2","b","")),Students!$A:$A,AQ$2)+countifs(Students!$V:$V,$P3,Students!$W:$W,$P$2&if($K3="S1","a",if($K3="S2","b","")),Students!$A:$A,AQ$2)+ countifs(Students!$D:$D,$S3,Students!$E:$E,$S$2&if($K3="S1","a",if($K3="S2","b","")),Students!$A:$A,AQ$2)+countifs(Students!$F:$F,$S3,Students!$G:$G,$S$2&if($K3="S1","a",if($K3="S2","b","")),Students!$A:$A,AQ$2)+countifs(Students!$H:$H,$S3,Students!$I:$I,$S$2&if($K3="S1","a",if($K3="S2","b","")),Students!$A:$A,AQ$2)+countifs(Students!$J:$J,$S3,Students!$K:$K,$S$2&if($K3="S1","a",if($K3="S2","b","")),Students!$A:$A,AQ$2)+countifs(Students!$L:$L,$S3,Students!$M:$M,$S$2&if($K3="S1","a",if($K3="S2","b","")),Students!$A:$A,AQ$2)+countifs(Students!$N:$N,$S3,Students!$O:$O,$S$2&if($K3="S1","a",if($K3="S2","b","")),Students!$A:$A,AQ$2)+countifs(Students!$P:$P,$S3,Students!$Q:$Q,$S$2&if($K3="S1","a",if($K3="S2","b","")),Students!$A:$A,AQ$2)+countifs(Students!$R:$R,$S3,Students!$S:$S,$S$2&if($K3="S1","a",if($K3="S2","b","")),Students!$A:$A,AQ$2)+countifs(Students!$T:$T,$S3,Students!$U:$U,$S$2&if($K3="S1","a",if($K3="S2","b","")),Students!$A:$A,AQ$2)+countifs(Students!$V:$V,$S3,Students!$W:$W,$S$2&if($K3="S1","a",if($K3="S2","b","")),Students!$A:$A,AQ$2)+ countifs(Students!$D:$D,$V3,Students!$E:$E,$V$2&if($K3="S1","a",if($K3="S2","b","")),Students!$A:$A,AQ$2)+countifs(Students!$F:$F,$V3,Students!$G:$G,$V$2&if($K3="S1","a",if($K3="S2","b","")),Students!$A:$A,AQ$2)+countifs(Students!$H:$H,$V3,Students!$I:$I,$V$2&if($K3="S1","a",if($K3="S2","b","")),Students!$A:$A,AQ$2)+countifs(Students!$J:$J,$V3,Students!$K:$K,$V$2&if($K3="S1","a",if($K3="S2","b","")),Students!$A:$A,AQ$2)+countifs(Students!$L:$L,$V3,Students!$M:$M,$V$2&if($K3="S1","a",if($K3="S2","b","")),Students!$A:$A,AQ$2)+countifs(Students!$N:$N,$V3,Students!$O:$O,$V$2&if($K3="S1","a",if($K3="S2","b","")),Students!$A:$A,AQ$2)+countifs(Students!$P:$P,$V3,Students!$Q:$Q,$V$2&if($K3="S1","a",if($K3="S2","b","")),Students!$A:$A,AQ$2)+countifs(Students!$R:$R,$V3,Students!$S:$S,$V$2&if($K3="S1","a",if($K3="S2","b","")),Students!$A:$A,AQ$2)+countifs(Students!$T:$T,$V3,Students!$U:$U,$V$2&if($K3="S1","a",if($K3="S2","b","")),Students!$A:$A,AQ$2)+countifs(Students!$V:$V,$V3,Students!$W:$W,$V$2&if($K3="S1","a",if($K3="S2","b","")),Students!$A:$A,AQ$2)+ countifs(Students!$D:$D,$Y3,Students!$E:$E,$Y$2&if($K3="S1","a",if($K3="S2","b","")),Students!$A:$A,AQ$2)+countifs(Students!$F:$F,$Y3,Students!$G:$G,$Y$2&if($K3="S1","a",if($K3="S2","b","")),Students!$A:$A,AQ$2)+countifs(Students!$H:$H,$Y3,Students!$I:$I,$Y$2&if($K3="S1","a",if($K3="S2","b","")),Students!$A:$A,AQ$2)+countifs(Students!$J:$J,$Y3,Students!$K:$K,$Y$2&if($K3="S1","a",if($K3="S2","b","")),Students!$A:$A,AQ$2)+countifs(Students!$L:$L,$Y3,Students!$M:$M,$Y$2&if($K3="S1","a",if($K3="S2","b","")),Students!$A:$A,AQ$2)+countifs(Students!$N:$N,$Y3,Students!$O:$O,$Y$2&if($K3="S1","a",if($K3="S2","b","")),Students!$A:$A,AQ$2)+countifs(Students!$P:$P,$Y3,Students!$Q:$Q,$Y$2&if($K3="S1","a",if($K3="S2","b","")),Students!$A:$A,AQ$2)+countifs(Students!$R:$R,$Y3,Students!$S:$S,$Y$2&if($K3="S1","a",if($K3="S2","b","")),Students!$A:$A,AQ$2)+countifs(Students!$T:$T,$Y3,Students!$U:$U,$Y$2&if($K3="S1","a",if($K3="S2","b","")),Students!$A:$A,AQ$2)+countifs(Students!$V:$V,$Y3,Students!$W:$W,$Y$2&if($K3="S1","a",if($K3="S2","b","")),Students!$A:$A,AQ$2)+ countifs(Students!$D:$D,$AB3,Students!$E:$E,$AB$2&if($K3="S1","a",if($K3="S2","b","")),Students!$A:$A,AQ$2)+countifs(Students!$F:$F,$AB3,Students!$G:$G,$AB$2&if($K3="S1","a",if($K3="S2","b","")),Students!$A:$A,AQ$2)+countifs(Students!$H:$H,$AB3,Students!$I:$I,$AB$2&if($K3="S1","a",if($K3="S2","b","")),Students!$A:$A,AQ$2)+countifs(Students!$J:$J,$AB3,Students!$K:$K,$AB$2&if($K3="S1","a",if($K3="S2","b","")),Students!$A:$A,AQ$2)+countifs(Students!$L:$L,$AB3,Students!$M:$M,$AB$2&if($K3="S1","a",if($K3="S2","b","")),Students!$A:$A,AQ$2)+countifs(Students!$N:$N,$AB3,Students!$O:$O,$AB$2&if($K3="S1","a",if($K3="S2","b","")),Students!$A:$A,AQ$2)+countifs(Students!$P:$P,$AB3,Students!$Q:$Q,$AB$2&if($K3="S1","a",if($K3="S2","b","")),Students!$A:$A,AQ$2)+countifs(Students!$R:$R,$AB3,Students!$S:$S,$AB$2&if($K3="S1","a",if($K3="S2","b","")),Students!$A:$A,AQ$2)+countifs(Students!$T:$T,$AB3,Students!$U:$U,$AB$2&if($K3="S1","a",if($K3="S2","b","")),Students!$A:$A,AQ$2)+countifs(Students!$V:$V,$AB3,Students!$W:$W,$AB$2&if($K3="S1","a",if($K3="S2","b","")),Students!$A:$A,AQ$2)+ countifs(Students!$D:$D,$AE3,Students!$E:$E,$AE$2&if($K3="S1","a",if($K3="S2","b","")),Students!$A:$A,AQ$2)+countifs(Students!$F:$F,$AE3,Students!$G:$G,$AE$2&if($K3="S1","a",if($K3="S2","b","")),Students!$A:$A,AQ$2)+countifs(Students!$H:$H,$AE3,Students!$I:$I,$AE$2&if($K3="S1","a",if($K3="S2","b","")),Students!$A:$A,AQ$2)+countifs(Students!$J:$J,$AE3,Students!$K:$K,$AE$2&if($K3="S1","a",if($K3="S2","b","")),Students!$A:$A,AQ$2)+countifs(Students!$L:$L,$AE3,Students!$M:$M,$AE$2&if($K3="S1","a",if($K3="S2","b","")),Students!$A:$A,AQ$2)+countifs(Students!$N:$N,$AE3,Students!$O:$O,$AE$2&if($K3="S1","a",if($K3="S2","b","")),Students!$A:$A,AQ$2)+countifs(Students!$P:$P,$AE3,Students!$Q:$Q,$AE$2&if($K3="S1","a",if($K3="S2","b","")),Students!$A:$A,AQ$2)+countifs(Students!$R:$R,$AE3,Students!$S:$S,$AE$2&if($K3="S1","a",if($K3="S2","b","")),Students!$A:$A,AQ$2)+countifs(Students!$T:$T,$AE3,Students!$U:$U,$AE$2&if($K3="S1","a",if($K3="S2","b","")),Students!$A:$A,AQ$2)+countifs(Students!$V:$V,$AE3,Students!$W:$W,$AE$2&if($K3="S1","a",if($K3="S2","b","")),Students!$A:$A,AQ$2)+ countifs(Students!$D:$D,$AH3,Students!$E:$E,$AH$2&if($K3="S1","a",if($K3="S2","b","")),Students!$A:$A,AQ$2)+countifs(Students!$F:$F,$AH3,Students!$G:$G,$AH$2&if($K3="S1","a",if($K3="S2","b","")),Students!$A:$A,AQ$2)+countifs(Students!$H:$H,$AH3,Students!$I:$I,$AH$2&if($K3="S1","a",if($K3="S2","b","")),Students!$A:$A,AQ$2)+countifs(Students!$J:$J,$AH3,Students!$K:$K,$AH$2&if($K3="S1","a",if($K3="S2","b","")),Students!$A:$A,AQ$2)+countifs(Students!$L:$L,$AH3,Students!$M:$M,$AH$2&if($K3="S1","a",if($K3="S2","b","")),Students!$A:$A,AQ$2)+countifs(Students!$N:$N,$AH3,Students!$O:$O,$AH$2&if($K3="S1","a",if($K3="S2","b","")),Students!$A:$A,AQ$2)+countifs(Students!$P:$P,$AH3,Students!$Q:$Q,$AH$2&if($K3="S1","a",if($K3="S2","b","")),Students!$A:$A,AQ$2)+countifs(Students!$R:$R,$AH3,Students!$S:$S,$AH$2&if($K3="S1","a",if($K3="S2","b","")),Students!$A:$A,AQ$2)+countifs(Students!$T:$T,$AH3,Students!$U:$U,$AH$2&if($K3="S1","a",if($K3="S2","b","")),Students!$A:$A,AQ$2)+countifs(Students!$V:$V,$AH3,Students!$W:$W,$AH$2&if($K3="S1","a",if($K3="S2","b","")),Students!$A:$A,AQ$2)+ countifs(Students!$D:$D,$AK3,Students!$E:$E,$AK$2&if($K3="S1","a",if($K3="S2","b","")),Students!$A:$A,AQ$2)+countifs(Students!$F:$F,$AK3,Students!$G:$G,$AK$2&if($K3="S1","a",if($K3="S2","b","")),Students!$A:$A,AQ$2)+countifs(Students!$H:$H,$AK3,Students!$I:$I,$AK$2&if($K3="S1","a",if($K3="S2","b","")),Students!$A:$A,AQ$2)+countifs(Students!$J:$J,$AK3,Students!$K:$K,$AK$2&if($K3="S1","a",if($K3="S2","b","")),Students!$A:$A,AQ$2)+countifs(Students!$L:$L,$AK3,Students!$M:$M,$AK$2&if($K3="S1","a",if($K3="S2","b","")),Students!$A:$A,AQ$2)+countifs(Students!$N:$N,$AK3,Students!$O:$O,$AK$2&if($K3="S1","a",if($K3="S2","b","")),Students!$A:$A,AQ$2)+countifs(Students!$P:$P,$AK3,Students!$Q:$Q,$AK$2&if($K3="S1","a",if($K3="S2","b","")),Students!$A:$A,AQ$2)+countifs(Students!$R:$R,$AK3,Students!$S:$S,$AK$2&if($K3="S1","a",if($K3="S2","b","")),Students!$A:$A,AQ$2)+countifs(Students!$T:$T,$AK3,Students!$U:$U,$AK$2&if($K3="S1","a",if($K3="S2","b","")),Students!$A:$A,AQ$2)+countifs(Students!$V:$V,$AK3,Students!$W:$W,$AK$2&if($K3="S1","a",if($K3="S2","b","")),Students!$A:$A,AQ$2)) -> 33 | AR3: =if($L3="","",countifs(Students!$D:$D,$P3,Students!$E:$E,$P$2&if($K3="S1","a",if($K3="S2","b","")),Students!$A:$A,AR$2)+countifs(Students!$F:$F,$P3,Students!$G:$G,$P$2&if($K3="S1","a",if($K3="S2","b","")),Students!$A:$A,AR$2)+countifs(Students!$H:$H,$P3,Students!$I:$I,$P$2&if($K3="S1","a",if($K3="S2","b","")),Students!$A:$A,AR$2)+countifs(Students!$J:$J,$P3,Students!$K:$K,$P$2&if($K3="S1","a",if($K3="S2","b","")),Students!$A:$A,AR$2)+countifs(Students!$L:$L,$P3,Students!$M:$M,$P$2&if($K3="S1","a",if($K3="S2","b","")),Students!$A:$A,AR$2)+countifs(Students!$N:$N,$P3,Students!$O:$O,$P$2&if($K3="S1","a",if($K3="S2","b","")),Students!$A:$A,AR$2)+countifs(Students!$P:$P,$P3,Students!$Q:$Q,$P$2&if($K3="S1","a",if($K3="S2","b","")),Students!$A:$A,AR$2)+countifs(Students!$R:$R,$P3,Students!$S:$S,$P$2&if($K3="S1","a",if($K3="S2","b","")),Students!$A:$A,AR$2)+countifs(Students!$T:$T,$P3,Students!$U:$U,$P$2&if($K3="S1","a",if($K3="S2","b","")),Students!$A:$A,AR$2)+countifs(Students!$V:$V,$P3,Students!$W:$W,$P$2&if($K3="S1","a",if($K3="S2","b","")),Students!$A:$A,AR$2)+ countifs(Students!$D:$D,$S3,Students!$E:$E,$S$2&if($K3="S1","a",if($K3="S2","b","")),Students!$A:$A,AR$2)+countifs(Students!$F:$F,$S3,Students!$G:$G,$S$2&if($K3="S1","a",if($K3="S2","b","")),Students!$A:$A,AR$2)+countifs(Students!$H:$H,$S3,Students!$I:$I,$S$2&if($K3="S1","a",if($K3="S2","b","")),Students!$A:$A,AR$2)+countifs(Students!$J:$J,$S3,Students!$K:$K,$S$2&if($K3="S1","a",if($K3="S2","b","")),Students!$A:$A,AR$2)+countifs(Students!$L:$L,$S3,Students!$M:$M,$S$2&if($K3="S1","a",if($K3="S2","b","")),Students!$A:$A,AR$2)+countifs(Students!$N:$N,$S3,Students!$O:$O,$S$2&if($K3="S1","a",if($K3="S2","b","")),Students!$A:$A,AR$2)+countifs(Students!$P:$P,$S3,Students!$Q:$Q,$S$2&if($K3="S1","a",if($K3="S2","b","")),Students!$A:$A,AR$2)+countifs(Students!$R:$R,$S3,Students!$S:$S,$S$2&if($K3="S1","a",if($K3="S2","b","")),Students!$A:$A,AR$2)+countifs(Students!$T:$T,$S3,Students!$U:$U,$S$2&if($K3="S1","a",if($K3="S2","b","")),Students!$A:$A,AR$2)+countifs(Students!$V:$V,$S3,Students!$W:$W,$S$2&if($K3="S1","a",if($K3="S2","b","")),Students!$A:$A,AR$2)+ countifs(Students!$D:$D,$V3,Students!$E:$E,$V$2&if($K3="S1","a",if($K3="S2","b","")),Students!$A:$A,AR$2)+countifs(Students!$F:$F,$V3,Students!$G:$G,$V$2&if($K3="S1","a",if($K3="S2","b","")),Students!$A:$A,AR$2)+countifs(Students!$H:$H,$V3,Students!$I:$I,$V$2&if($K3="S1","a",if($K3="S2","b","")),Students!$A:$A,AR$2)+countifs(Students!$J:$J,$V3,Students!$K:$K,$V$2&if($K3="S1","a",if($K3="S2","b","")),Students!$A:$A,AR$2)+countifs(Students!$L:$L,$V3,Students!$M:$M,$V$2&if($K3="S1","a",if($K3="S2","b","")),Students!$A:$A,AR$2)+countifs(Students!$N:$N,$V3,Students!$O:$O,$V$2&if($K3="S1","a",if($K3="S2","b","")),Students!$A:$A,AR$2)+countifs(Students!$P:$P,$V3,Students!$Q:$Q,$V$2&if($K3="S1","a",if($K3="S2","b","")),Students!$A:$A,AR$2)+countifs(Students!$R:$R,$V3,Students!$S:$S,$V$2&if($K3="S1","a",if($K3="S2","b","")),Students!$A:$A,AR$2)+countifs(Students!$T:$T,$V3,Students!$U:$U,$V$2&if($K3="S1","a",if($K3="S2","b","")),Students!$A:$A,AR$2)+countifs(Students!$V:$V,$V3,Students!$W:$W,$V$2&if($K3="S1","a",if($K3="S2","b","")),Students!$A:$A,AR$2)+ countifs(Students!$D:$D,$Y3,Students!$E:$E,$Y$2&if($K3="S1","a",if($K3="S2","b","")),Students!$A:$A,AR$2)+countifs(Students!$F:$F,$Y3,Students!$G:$G,$Y$2&if($K3="S1","a",if($K3="S2","b","")),Students!$A:$A,AR$2)+countifs(Students!$H:$H,$Y3,Students!$I:$I,$Y$2&if($K3="S1","a",if($K3="S2","b","")),Students!$A:$A,AR$2)+countifs(Students!$J:$J,$Y3,Students!$K:$K,$Y$2&if($K3="S1","a",if($K3="S2","b","")),Students!$A:$A,AR$2)+countifs(Students!$L:$L,$Y3,Students!$M:$M,$Y$2&if($K3="S1","a",if($K3="S2","b","")),Students!$A:$A,AR$2)+countifs(Students!$N:$N,$Y3,Students!$O:$O,$Y$2&if($K3="S1","a",if($K3="S2","b","")),Students!$A:$A,AR$2)+countifs(Students!$P:$P,$Y3,Students!$Q:$Q,$Y$2&if($K3="S1","a",if($K3="S2","b","")),Students!$A:$A,AR$2)+countifs(Students!$R:$R,$Y3,Students!$S:$S,$Y$2&if($K3="S1","a",if($K3="S2","b","")),Students!$A:$A,AR$2)+countifs(Students!$T:$T,$Y3,Students!$U:$U,$Y$2&if($K3="S1","a",if($K3="S2","b","")),Students!$A:$A,AR$2)+countifs(Students!$V:$V,$Y3,Students!$W:$W,$Y$2&if($K3="S1","a",if($K3="S2","b","")),Students!$A:$A,AR$2)+ countifs(Students!$D:$D,$AB3,Students!$E:$E,$AB$2&if($K3="S1","a",if($K3="S2","b","")),Students!$A:$A,AR$2)+countifs(Students!$F:$F,$AB3,Students!$G:$G,$AB$2&if($K3="S1","a",if($K3="S2","b","")),Students!$A:$A,AR$2)+countifs(Students!$H:$H,$AB3,Students!$I:$I,$AB$2&if($K3="S1","a",if($K3="S2","b","")),Students!$A:$A,AR$2)+countifs(Students!$J:$J,$AB3,Students!$K:$K,$AB$2&if($K3="S1","a",if($K3="S2","b","")),Students!$A:$A,AR$2)+countifs(Students!$L:$L,$AB3,Students!$M:$M,$AB$2&if($K3="S1","a",if($K3="S2","b","")),Students!$A:$A,AR$2)+countifs(Students!$N:$N,$AB3,Students!$O:$O,$AB$2&if($K3="S1","a",if($K3="S2","b","")),Students!$A:$A,AR$2)+countifs(Students!$P:$P,$AB3,Students!$Q:$Q,$AB$2&if($K3="S1","a",if($K3="S2","b","")),Students!$A:$A,AR$2)+countifs(Students!$R:$R,$AB3,Students!$S:$S,$AB$2&if($K3="S1","a",if($K3="S2","b","")),Students!$A:$A,AR$2)+countifs(Students!$T:$T,$AB3,Students!$U:$U,$AB$2&if($K3="S1","a",if($K3="S2","b","")),Students!$A:$A,AR$2)+countifs(Students!$V:$V,$AB3,Students!$W:$W,$AB$2&if($K3="S1","a",if($K3="S2","b","")),Students!$A:$A,AR$2)+ countifs(Students!$D:$D,$AE3,Students!$E:$E,$AE$2&if($K3="S1","a",if($K3="S2","b","")),Students!$A:$A,AR$2)+countifs(Students!$F:$F,$AE3,Students!$G:$G,$AE$2&if($K3="S1","a",if($K3="S2","b","")),Students!$A:$A,AR$2)+countifs(Students!$H:$H,$AE3,Students!$I:$I,$AE$2&if($K3="S1","a",if($K3="S2","b","")),Students!$A:$A,AR$2)+countifs(Students!$J:$J,$AE3,Students!$K:$K,$AE$2&if($K3="S1","a",if($K3="S2","b","")),Students!$A:$A,AR$2)+countifs(Students!$L:$L,$AE3,Students!$M:$M,$AE$2&if($K3="S1","a",if($K3="S2","b","")),Students!$A:$A,AR$2)+countifs(Students!$N:$N,$AE3,Students!$O:$O,$AE$2&if($K3="S1","a",if($K3="S2","b","")),Students!$A:$A,AR$2)+countifs(Students!$P:$P,$AE3,Students!$Q:$Q,$AE$2&if($K3="S1","a",if($K3="S2","b","")),Students!$A:$A,AR$2)+countifs(Students!$R:$R,$AE3,Students!$S:$S,$AE$2&if($K3="S1","a",if($K3="S2","b","")),Students!$A:$A,AR$2)+countifs(Students!$T:$T,$AE3,Students!$U:$U,$AE$2&if($K3="S1","a",if($K3="S2","b","")),Students!$A:$A,AR$2)+countifs(Students!$V:$V,$AE3,Students!$W:$W,$AE$2&if($K3="S1","a",if($K3="S2","b","")),Students!$A:$A,AR$2)+ countifs(Students!$D:$D,$AH3,Students!$E:$E,$AH$2&if($K3="S1","a",if($K3="S2","b","")),Students!$A:$A,AR$2)+countifs(Students!$F:$F,$AH3,Students!$G:$G,$AH$2&if($K3="S1","a",if($K3="S2","b","")),Students!$A:$A,AR$2)+countifs(Students!$H:$H,$AH3,Students!$I:$I,$AH$2&if($K3="S1","a",if($K3="S2","b","")),Students!$A:$A,AR$2)+countifs(Students!$J:$J,$AH3,Students!$K:$K,$AH$2&if($K3="S1","a",if($K3="S2","b","")),Students!$A:$A,AR$2)+countifs(Students!$L:$L,$AH3,Students!$M:$M,$AH$2&if($K3="S1","a",if($K3="S2","b","")),Students!$A:$A,AR$2)+countifs(Students!$N:$N,$AH3,Students!$O:$O,$AH$2&if($K3="S1","a",if($K3="S2","b","")),Students!$A:$A,AR$2)+countifs(Students!$P:$P,$AH3,Students!$Q:$Q,$AH$2&if($K3="S1","a",if($K3="S2","b","")),Students!$A:$A,AR$2)+countifs(Students!$R:$R,$AH3,Students!$S:$S,$AH$2&if($K3="S1","a",if($K3="S2","b","")),Students!$A:$A,AR$2)+countifs(Students!$T:$T,$AH3,Students!$U:$U,$AH$2&if($K3="S1","a",if($K3="S2","b","")),Students!$A:$A,AR$2)+countifs(Students!$V:$V,$AH3,Students!$W:$W,$AH$2&if($K3="S1","a",if($K3="S2","b","")),Students!$A:$A,AR$2)+ countifs(Students!$D:$D,$AK3,Students!$E:$E,$AK$2&if($K3="S1","a",if($K3="S2","b","")),Students!$A:$A,AR$2)+countifs(Students!$F:$F,$AK3,Students!$G:$G,$AK$2&if($K3="S1","a",if($K3="S2","b","")),Students!$A:$A,AR$2)+countifs(Students!$H:$H,$AK3,Students!$I:$I,$AK$2&if($K3="S1","a",if($K3="S2","b","")),Students!$A:$A,AR$2)+countifs(Students!$J:$J,$AK3,Students!$K:$K,$AK$2&if($K3="S1","a",if($K3="S2","b","")),Students!$A:$A,AR$2)+countifs(Students!$L:$L,$AK3,Students!$M:$M,$AK$2&if($K3="S1","a",if($K3="S2","b","")),Students!$A:$A,AR$2)+countifs(Students!$N:$N,$AK3,Students!$O:$O,$AK$2&if($K3="S1","a",if($K3="S2","b","")),Students!$A:$A,AR$2)+countifs(Students!$P:$P,$AK3,Students!$Q:$Q,$AK$2&if($K3="S1","a",if($K3="S2","b","")),Students!$A:$A,AR$2)+countifs(Students!$R:$R,$AK3,Students!$S:$S,$AK$2&if($K3="S1","a",if($K3="S2","b","")),Students!$A:$A,AR$2)+countifs(Students!$T:$T,$AK3,Students!$U:$U,$AK$2&if($K3="S1","a",if($K3="S2","b","")),Students!$A:$A,AR$2)+countifs(Students!$V:$V,$AK3,Students!$W:$W,$AK$2&if($K3="S1","a",if($K3="S2","b","")),Students!$A:$A,AR$2)) -> 44 | AS3: =if($L3="","",countifs(Students!$D:$D,$P3,Students!$E:$E,$P$2&if($K3="S1","a",if($K3="S2","b","")),Students!$A:$A,AS$2)+countifs(Students!$F:$F,$P3,Students!$G:$G,$P$2&if($K3="S1","a",if($K3="S2","b","")),Students!$A:$A,AS$2)+countifs(Students!$H:$H,$P3,Students!$I:$I,$P$2&if($K3="S1","a",if($K3="S2","b","")),Students!$A:$A,AS$2)+countifs(Students!$J:$J,$P3,Students!$K:$K,$P$2&if($K3="S1","a",if($K3="S2","b","")),Students!$A:$A,AS$2)+countifs(Students!$L:$L,$P3,Students!$M:$M,$P$2&if($K3="S1","a",if($K3="S2","b","")),Students!$A:$A,AS$2)+countifs(Students!$N:$N,$P3,Students!$O:$O,$P$2&if($K3="S1","a",if($K3="S2","b","")),Students!$A:$A,AS$2)+countifs(Students!$P:$P,$P3,Students!$Q:$Q,$P$2&if($K3="S1","a",if($K3="S2","b","")),Students!$A:$A,AS$2)+countifs(Students!$R:$R,$P3,Students!$S:$S,$P$2&if($K3="S1","a",if($K3="S2","b","")),Students!$A:$A,AS$2)+countifs(Students!$T:$T,$P3,Students!$U:$U,$P$2&if($K3="S1","a",if($K3="S2","b","")),Students!$A:$A,AS$2)+countifs(Students!$V:$V,$P3,Students!$W:$W,$P$2&if($K3="S1","a",if($K3="S2","b","")),Students!$A:$A,AS$2)+ countifs(Students!$D:$D,$S3,Students!$E:$E,$S$2&if($K3="S1","a",if($K3="S2","b","")),Students!$A:$A,AS$2)+countifs(Students!$F:$F,$S3,Students!$G:$G,$S$2&if($K3="S1","a",if($K3="S2","b","")),Students!$A:$A,AS$2)+countifs(Students!$H:$H,$S3,Students!$I:$I,$S$2&if($K3="S1","a",if($K3="S2","b","")),Students!$A:$A,AS$2)+countifs(Students!$J:$J,$S3,Students!$K:$K,$S$2&if($K3="S1","a",if($K3="S2","b","")),Students!$A:$A,AS$2)+countifs(Students!$L:$L,$S3,Students!$M:$M,$S$2&if($K3="S1","a",if($K3="S2","b","")),Students!$A:$A,AS$2)+countifs(Students!$N:$N,$S3,Students!$O:$O,$S$2&if($K3="S1","a",if($K3="S2","b","")),Students!$A:$A,AS$2)+countifs(Students!$P:$P,$S3,Students!$Q:$Q,$S$2&if($K3="S1","a",if($K3="S2","b","")),Students!$A:$A,AS$2)+countifs(Students!$R:$R,$S3,Students!$S:$S,$S$2&if($K3="S1","a",if($K3="S2","b","")),Students!$A:$A,AS$2)+countifs(Students!$T:$T,$S3,Students!$U:$U,$S$2&if($K3="S1","a",if($K3="S2","b","")),Students!$A:$A,AS$2)+countifs(Students!$V:$V,$S3,Students!$W:$W,$S$2&if($K3="S1","a",if($K3="S2","b","")),Students!$A:$A,AS$2)+ countifs(Students!$D:$D,$V3,Students!$E:$E,$V$2&if($K3="S1","a",if($K3="S2","b","")),Students!$A:$A,AS$2)+countifs(Students!$F:$F,$V3,Students!$G:$G,$V$2&if($K3="S1","a",if($K3="S2","b","")),Students!$A:$A,AS$2)+countifs(Students!$H:$H,$V3,Students!$I:$I,$V$2&if($K3="S1","a",if($K3="S2","b","")),Students!$A:$A,AS$2)+countifs(Students!$J:$J,$V3,Students!$K:$K,$V$2&if($K3="S1","a",if($K3="S2","b","")),Students!$A:$A,AS$2)+countifs(Students!$L:$L,$V3,Students!$M:$M,$V$2&if($K3="S1","a",if($K3="S2","b","")),Students!$A:$A,AS$2)+countifs(Students!$N:$N,$V3,Students!$O:$O,$V$2&if($K3="S1","a",if($K3="S2","b","")),Students!$A:$A,AS$2)+countifs(Students!$P:$P,$V3,Students!$Q:$Q,$V$2&if($K3="S1","a",if($K3="S2","b","")),Students!$A:$A,AS$2)+countifs(Students!$R:$R,$V3,Students!$S:$S,$V$2&if($K3="S1","a",if($K3="S2","b","")),Students!$A:$A,AS$2)+countifs(Students!$T:$T,$V3,Students!$U:$U,$V$2&if($K3="S1","a",if($K3="S2","b","")),Students!$A:$A,AS$2)+countifs(Students!$V:$V,$V3,Students!$W:$W,$V$2&if($K3="S1","a",if($K3="S2","b","")),Students!$A:$A,AS$2)+ countifs(Students!$D:$D,$Y3,Students!$E:$E,$Y$2&if($K3="S1","a",if($K3="S2","b","")),Students!$A:$A,AS$2)+countifs(Students!$F:$F,$Y3,Students!$G:$G,$Y$2&if($K3="S1","a",if($K3="S2","b","")),Students!$A:$A,AS$2)+countifs(Students!$H:$H,$Y3,Students!$I:$I,$Y$2&if($K3="S1","a",if($K3="S2","b","")),Students!$A:$A,AS$2)+countifs(Students!$J:$J,$Y3,Students!$K:$K,$Y$2&if($K3="S1","a",if($K3="S2","b","")),Students!$A:$A,AS$2)+countifs(Students!$L:$L,$Y3,Students!$M:$M,$Y$2&if($K3="S1","a",if($K3="S2","b","")),Students!$A:$A,AS$2)+countifs(Students!$N:$N,$Y3,Students!$O:$O,$Y$2&if($K3="S1","a",if($K3="S2","b","")),Students!$A:$A,AS$2)+countifs(Students!$P:$P,$Y3,Students!$Q:$Q,$Y$2&if($K3="S1","a",if($K3="S2","b","")),Students!$A:$A,AS$2)+countifs(Students!$R:$R,$Y3,Students!$S:$S,$Y$2&if($K3="S1","a",if($K3="S2","b","")),Students!$A:$A,AS$2)+countifs(Students!$T:$T,$Y3,Students!$U:$U,$Y$2&if($K3="S1","a",if($K3="S2","b","")),Students!$A:$A,AS$2)+countifs(Students!$V:$V,$Y3,Students!$W:$W,$Y$2&if($K3="S1","a",if($K3="S2","b","")),Students!$A:$A,AS$2)+ countifs(Students!$D:$D,$AB3,Students!$E:$E,$AB$2&if($K3="S1","a",if($K3="S2","b","")),Students!$A:$A,AS$2)+countifs(Students!$F:$F,$AB3,Students!$G:$G,$AB$2&if($K3="S1","a",if($K3="S2","b","")),Students!$A:$A,AS$2)+countifs(Students!$H:$H,$AB3,Students!$I:$I,$AB$2&if($K3="S1","a",if($K3="S2","b","")),Students!$A:$A,AS$2)+countifs(Students!$J:$J,$AB3,Students!$K:$K,$AB$2&if($K3="S1","a",if($K3="S2","b","")),Students!$A:$A,AS$2)+countifs(Students!$L:$L,$AB3,Students!$M:$M,$AB$2&if($K3="S1","a",if($K3="S2","b","")),Students!$A:$A,AS$2)+countifs(Students!$N:$N,$AB3,Students!$O:$O,$AB$2&if($K3="S1","a",if($K3="S2","b","")),Students!$A:$A,AS$2)+countifs(Students!$P:$P,$AB3,Students!$Q:$Q,$AB$2&if($K3="S1","a",if($K3="S2","b","")),Students!$A:$A,AS$2)+countifs(Students!$R:$R,$AB3,Students!$S:$S,$AB$2&if($K3="S1","a",if($K3="S2","b","")),Students!$A:$A,AS$2)+countifs(Students!$T:$T,$AB3,Students!$U:$U,$AB$2&if($K3="S1","a",if($K3="S2","b","")),Students!$A:$A,AS$2)+countifs(Students!$V:$V,$AB3,Students!$W:$W,$AB$2&if($K3="S1","a",if($K3="S2","b","")),Students!$A:$A,AS$2)+ countifs(Students!$D:$D,$AE3,Students!$E:$E,$AE$2&if($K3="S1","a",if($K3="S2","b","")),Students!$A:$A,AS$2)+countifs(Students!$F:$F,$AE3,Students!$G:$G,$AE$2&if($K3="S1","a",if($K3="S2","b","")),Students!$A:$A,AS$2)+countifs(Students!$H:$H,$AE3,Students!$I:$I,$AE$2&if($K3="S1","a",if($K3="S2","b","")),Students!$A:$A,AS$2)+countifs(Students!$J:$J,$AE3,Students!$K:$K,$AE$2&if($K3="S1","a",if($K3="S2","b","")),Students!$A:$A,AS$2)+countifs(Students!$L:$L,$AE3,Students!$M:$M,$AE$2&if($K3="S1","a",if($K3="S2","b","")),Students!$A:$A,AS$2)+countifs(Students!$N:$N,$AE3,Students!$O:$O,$AE$2&if($K3="S1","a",if($K3="S2","b","")),Students!$A:$A,AS$2)+countifs(Students!$P:$P,$AE3,Students!$Q:$Q,$AE$2&if($K3="S1","a",if($K3="S2","b","")),Students!$A:$A,AS$2)+countifs(Students!$R:$R,$AE3,Students!$S:$S,$AE$2&if($K3="S1","a",if($K3="S2","b","")),Students!$A:$A,AS$2)+countifs(Students!$T:$T,$AE3,Students!$U:$U,$AE$2&if($K3="S1","a",if($K3="S2","b","")),Students!$A:$A,AS$2)+countifs(Students!$V:$V,$AE3,Students!$W:$W,$AE$2&if($K3="S1","a",if($K3="S2","b","")),Students!$A:$A,AS$2)+ countifs(Students!$D:$D,$AH3,Students!$E:$E,$AH$2&if($K3="S1","a",if($K3="S2","b","")),Students!$A:$A,AS$2)+countifs(Students!$F:$F,$AH3,Students!$G:$G,$AH$2&if($K3="S1","a",if($K3="S2","b","")),Students!$A:$A,AS$2)+countifs(Students!$H:$H,$AH3,Students!$I:$I,$AH$2&if($K3="S1","a",if($K3="S2","b","")),Students!$A:$A,AS$2)+countifs(Students!$J:$J,$AH3,Students!$K:$K,$AH$2&if($K3="S1","a",if($K3="S2","b","")),Students!$A:$A,AS$2)+countifs(Students!$L:$L,$AH3,Students!$M:$M,$AH$2&if($K3="S1","a",if($K3="S2","b","")),Students!$A:$A,AS$2)+countifs(Students!$N:$N,$AH3,Students!$O:$O,$AH$2&if($K3="S1","a",if($K3="S2","b","")),Students!$A:$A,AS$2)+countifs(Students!$P:$P,$AH3,Students!$Q:$Q,$AH$2&if($K3="S1","a",if($K3="S2","b","")),Students!$A:$A,AS$2)+countifs(Students!$R:$R,$AH3,Students!$S:$S,$AH$2&if($K3="S1","a",if($K3="S2","b","")),Students!$A:$A,AS$2)+countifs(Students!$T:$T,$AH3,Students!$U:$U,$AH$2&if($K3="S1","a",if($K3="S2","b","")),Students!$A:$A,AS$2)+countifs(Students!$V:$V,$AH3,Students!$W:$W,$AH$2&if($K3="S1","a",if($K3="S2","b","")),Students!$A:$A,AS$2)+ countifs(Students!$D:$D,$AK3,Students!$E:$E,$AK$2&if($K3="S1","a",if($K3="S2","b","")),Students!$A:$A,AS$2)+countifs(Students!$F:$F,$AK3,Students!$G:$G,$AK$2&if($K3="S1","a",if($K3="S2","b","")),Students!$A:$A,AS$2)+countifs(Students!$H:$H,$AK3,Students!$I:$I,$AK$2&if($K3="S1","a",if($K3="S2","b","")),Students!$A:$A,AS$2)+countifs(Students!$J:$J,$AK3,Students!$K:$K,$AK$2&if($K3="S1","a",if($K3="S2","b","")),Students!$A:$A,AS$2)+countifs(Students!$L:$L,$AK3,Students!$M:$M,$AK$2&if($K3="S1","a",if($K3="S2","b","")),Students!$A:$A,AS$2)+countifs(Students!$N:$N,$AK3,Students!$O:$O,$AK$2&if($K3="S1","a",if($K3="S2","b","")),Students!$A:$A,AS$2)+countifs(Students!$P:$P,$AK3,Students!$Q:$Q,$AK$2&if($K3="S1","a",if($K3="S2","b","")),Students!$A:$A,AS$2)+countifs(Students!$R:$R,$AK3,Students!$S:$S,$AK$2&if($K3="S1","a",if($K3="S2","b","")),Students!$A:$A,AS$2)+countifs(Students!$T:$T,$AK3,Students!$U:$U,$AK$2&if($K3="S1","a",if($K3="S2","b","")),Students!$A:$A,AS$2)+countifs(Students!$V:$V,$AK3,Students!$W:$W,$AK$2&if($K3="S1","a",if($K3="S2","b","")),Students!$A:$A,AS$2)) -> 20
