Workbook

Sheet Special Requests
A1: Special Request | B1: Reason for special request | C1: If request is for a specific student, please select their name from the drop-down menu: | D1: {=if(ROW(D:D)=1,"Grade Level (Automated)",if(C:C="","",vlookup(C:C,{Students!C:C,Students!A:A},2,false)))} -> Grade Level (Automated) | E1: Date Approved by Principal | F1: Date Approved by Director of Learning | G1: Date Approved by HR (if applicable)
A2: Common planning period all teachers of common courses in this link | B2: To ensure that co-teachers can teach | F2: 45037
A3: Co planning at least 1 period a week: Vivian Perez and Brandon Berry. | B3: To ensure that co-teachers can teach
A4: Co planning at least 1 period a week: Vivian Perez and Andrea Gil | B4: To ensure that co-teachers can teach
A5: Co planning at least 1 period a week: Vivian Perez and Aldair | B5: To ensure that co-teachers can teach
A6: New Teachers have 1 period a week in common off (by groups i.e. the Math/Science teachers have 1 common block) | B6: For Curriculum depatment to meet with new teachers in small groups
A7: Co planning at least 1 period a week: New LC Math teacher and Eich Schober | B7: To ensure that co-teachers can teach
A8: Co planning at least 1 period a week: New LC Math teacher and Ari Holstein | B8: To ensure that co-teachers can teach
A9: Co planning at least 1 period a week: New LC Math teacher and Rachel McGargon | B9: To ensure that co-teachers can teach

Sheet 🅿️Perla
A1: Courses | B1: freq | C1: grades
A2: Core classes | B2: 4 | C2: All | E2: 9 courses | F2: 6th | G2: Teachers | H2: 5 consecutive including advisory
A3: PE | B3: 2 | C3: All | G3: Art | H3: 18 hours
A4: Tech | B4: 1 | C4: All | G4: Band | H4: 18 hours
A5: Band | B5: 1 | C5: 6th | G5: Core Teacher | H5: 15 hours
A6: Band | B6: 2 | C6: 7th,8th | G6: Miralles Split department - Own class room | I6: 9 hours 2 teachers | J6: 12 hours | K6: Normally 6 sections grade | L6: Idea 8 sections per grade level | M6: tech room always available
A7: Art | B7: 1 | C7: 6th | E7: 8 Courses | F7: 7th,8th | G7: PE | H7: 18 hours
A8: Art | B8: 2 | C8: 7th,8th | G8: Science only on Labs
G9: Section 1 English | H9: Always co-teaching | I9: All grades | J9: Isaías needs to be with math co-teacher
G10: Section 1 Math | H10: Always co-teaching | I10: All grades | J10: Sofia needs to be with English co-teacher
G11: Tech | H11: 18 hours

Sheet Timeline
A1: Item | B1: Description | C1: Person Responsible | D1: Due Date | E1: Additonal Information | F1: Links
A2: 7th Grade Math MAP Test | B2: Have 7th grade students take Math MAP Growth test (to determine who can take Algebra in 8th grade) | C2: Principal | D2: January | E2: If a student wants to be reconsidered, they can take the 8th Grade Khan Academy Math course and show sufficient growth in their Spring MAP test.
A3: Define plan de estudios | B3: Define new courses and changes | C3: Principal | D3: January | E3: CPC and SCC give feedback and Consejo Directivo approves.
A4: Identify students for English and Spanish Intervention | B4: Use Fall MAP test scores and Jan F&P (for 5th grade) and literably (6th and 7th) and grades. Teachers give final recommendation. | C4: Principal | D4: February
A5: Student choices | B5: Students select their courses. Share student selections with Sam to process which courses do not have sufficient enrollment to be created. | C5: Principal | D5: 44621
A6: Analysis of Student Choices | B6: Sam shares the list of courses that have to be eliminated because of insufficient enrollment. | C6: Sam | D6: 44635
A7: New Student Choices | B7: Contact students in the courses that were eliminated due to insufficient enrollment to select a replacement course. | C7: Principal | D7: 44652
A8: Scheduling Special Requests | B8: Make a list of all scheduling special requests in the Tab called "Special Requests" | C8: Principal | D8: 44652
A9: Students who can't be together | B9: Make a list of all students that can't be together or must be together in the tab called "Student Groupings". It is important to create these requests after a collaborative discussion and to keep these requests down to a minimum. | C9: Principal | D9: 44652
A10: Receive Schedule | B10: Turn in finished schedule for approval and revision | C10: Sam | D10: 44682 | E10: After the final schedule is turned in, each school is responsible for making their own changes to the schedule if new changes are needed. (Sam can help if the change is very difficult).
A11: Upload Schedule to Powerschool | B11: Upload the Schedule into Powerschool | C11: Administrative Assistants | D11: 44743
A12: Identify students for Co-taught classes | B12: Use TCS criteria to identify the LC and non- LC students that will be in co-taught ELA, Spanish, and Math for 6-8th grade | C12: ADOL SS and MS LC Coordinator | D12: 45047
A13: Co-planning | B13: Identify teachers that need to have at least 1 period a week for co-planning | C13: VP and P | D13: 45047

Sheet Schedule
A1: Number of students who have not chosen elective: | E1: =countifs(Students!T:T,"#N/A") -> 0 | L1: Schedule Conflicts: | P1: =countifs(Students!AB:AB,">0") -> 0 | R1: % 6-8 done: | T1: =iferror(rounddown(sum(Students!AA:AA)/(rounddown(countifs(Students!B2:B86,"<>"&""),0)*6),2),0) -> 1 | V1: Over 24 students: | Y1: =countifs(O3:O27,">24")+countifs(R3:R27,">24")+countifs(U3:U27,">24")+countifs(X3:X27,">24")+countifs(AA3:AA27,">24")+countifs(AD3:AD27,">24")+countifs(#REF!,">24") -> 18 | AA1: ERRORS (ghost classes): | AC1: =sum('Ghost Classes'!E:E) -> 0
A2: Grade Level | B2: Block | C2: Day A | D2: Day B | E2: Day C | F2: Day D | G2: Day E | I2: Room | J2: Quarter | K2: Scheme | L2: Teacher | M2: 1 | N2: S | O2: {=if(ROW(O2:O86)=2,"#",if(M2:M86="","",if($J2:$J86="S1",countifs(Students!$P:$P,M$2:M86,Students!$Q:$Q,M$2&$K2:$K86),if($J2:$J86="S2",countifs(Students!$R:$R,M$2:M86,Students!$S:$S,M$2&$K2:$K86),countifs('Students (Vertical)'!$D:$D,M$2:M86,'Students (Vertical)'!$E:$E,M$2&$K2:$K86)))))} -> # | P2: 2 | Q2: S | R2: {=if(ROW(R2:R86)=2,"#",if(P2:P86="","",if($J2:$J86="S1",countifs(Students!$P:$P,P$2:P86,Students!$Q:$Q,P$2&$K2:$K86),if($J2:$J86="S2",countifs(Students!$R:$R,P$2:P86,Students!$S:$S,P$2&$K2:$K86),countifs('Students (Vertical)'!$D:$D,P$2:P86,'Students (Vertical)'!$E:$E,P$2&$K2:$K86)))))} -> # | S2: 3 | T2: S | U2: {=if(ROW(U2:U86)=2,"#",if(S2:S86="","",if($J2:$J86="S1",countifs(Students!$P:$P,S$2:S86,Students!$Q:$Q,S$2&$K2:$K86),if($J2:$J86="S2",countifs(Students!$R:$R,S$2:S86,Students!$S:$S,S$2&$K2:$K86),countifs('Students (Vertical)'!$D:$D,S$2:S86,'Students (Vertical)'!$E:$E,S$2&$K2:$K86)))))} -> # | V2: 4 | W2: S | X2: {=if(ROW(X2:X86)=2,"#",if(V2:V86="","",if($J2:$J86="S1",countifs(Students!$P:$P,V$2:V86,Students!$Q:$Q,V$2&$K2:$K86),if($J2:$J86="S2",countifs(Students!$R:$R,V$2:V86,Students!$S:$S,V$2&$K2:$K86),countifs('Students (Vertical)'!$D:$D,V$2:V86,'Students (Vertical)'!$E:$E,V$2&$K2:$K86)))))} -> # | Y2: 5 | Z2: S | AA2: {=if(ROW(AA2:AA86)=2,"#",if(Y2:Y86="","",if($J2:$J86="S1",countifs(Students!$P:$P,Y$2:Y86,Students!$Q:$Q,Y$2&$K2:$K86),if($J2:$J86="S2",countifs(Students!$R:$R,Y$2:Y86,Students!$S:$S,Y$2&$K2:$K86),countifs('Students (Vertical)'!$D:$D,Y$2:Y86,'Students (Vertical)'!$E:$E,Y$2&$K2:$K86)))))} -> # | AB2: 6 | AC2: S | AD2: {=if(ROW(AD2:AD86)=2,"#",if(AB2:AB86="","",if($J2:$J86="S1",countifs(Students!$P:$P,AB$2:AB86,Students!$Q:$Q,AB$2&$K2:$K86),if($J2:$J86="S2",countifs(Students!$R:$R,AB$2:AB86,Students!$S:$S,AB$2&$K2:$K86),countifs('Students (Vertical)'!$D:$D,AB$2:AB86,'Students (Vertical)'!$E:$E,AB$2&$K2:$K86)))))} -> # | AE2: G6 | AF2: G7 | AG2: G8
A3: All | B3: 1 | C3: 1a | D3: 6b | E3: 3a | F3: 4a | G3: 5b | I3: 329 | J3: S1 | K3: a | L3: Dioger | M3: Art 7 | N3: 1 | O3: 11 | P3: Art 6 | Q3: 3 | R3: 12 | V3: Art 6 | W3: 5 | X3: 12 | Y3: Art 8 | Z3: 2 | AA3: 10 | AB3: Art 7 | AC3: 5 | AD3: 23 | AG3: 1 | AH3: {=sort(unique(L3:L70))} -> Adriana RamIrez
B4: 2 | C4: 2a | D4: 5b | E4: 2a | F4: 1a | G4: 6a | I4: 329 | J4: S1 | K4: b | L4: Dioger | M4: Art 6 | N4: 1 | O4: 12 | P4: Art 7 | Q4: 3 | R4: 11 | AB4: Art 6 | AC4: 7 | AD4: 12 | AF4: 1 | AG4: 1 | AH4: Ana MarIa Rincon
B5: 3 | C5: 3a | D5: 3b | E5: 5a | F5: 2b | G5: x-block | I5: 329 | J5: S2 | K5: a | L5: Dioger | M5: Art 7 | N5: 2 | O5: 10 | P5: Art 6 | Q5: 4 | R5: 12 | V5: Art 6 | W5: 6 | X5: 12 | Y5: Art 8 | Z5: 3 | AA5: 10 | AF5: 1 | AH5: Andrea Gil
B6: 4 | C6: 4a | D6: 1b | E6: 6a | F6: 3b | G6: 4b | I6: 329 | J6: S2 | K6: b | L6: Dioger | M6: Art 6 | N6: 2 | O6: 11 | P6: Art 7 | Q6: 4 | R6: 11 | V6: Art 8 | W6: 1 | X6: 25 | AB6: Art 6 | AC6: 8 | AD6: 12 | AE6: 1 | AH6: Ben Light
B7: 5 | C7: 5a | D7: 2b | E7: 4b | F7: 6b | G7: 1b | I7: 617 | J7: S1 | K7: a | L7: Luisa | M7: Tech 7 | N7: 1 | O7: 10 | P7: Tech 6 | Q7: 3 | R7: 12 | V7: Tech 6 | W7: 5 | X7: 12 | Y7: Tech 8 | Z7: 2 | AA7: 10 | AE7: 1 | AG7: 1 | AH7: Brandon Berry
I8: 617 | J8: S1 | K8: b | L8: Luisa | M8: Tech 6 | N8: 1 | O8: 11 | P8: Tech 7 | Q8: 3 | R8: 11 | V8: Tech 8 | W8: 1 | X8: 25 | AB8: Tech 6 | AC8: 7 | AD8: 12 | AG8: 1 | AH8: Chris Matthews
I9: 617 | J9: S2 | K9: a | L9: Luisa | M9: Tech 7 | N9: 2 | O9: 11 | P9: Tech 6 | Q9: 4 | R9: 12 | V9: Tech 6 | W9: 6 | X9: 12 | Y9: Tech 8 | Z9: 3 | AA9: 10 | AB9: Tech 7 | AC9: 5 | AD9: 23 | AF9: 1 | AH9: Dioger
B10: 1 | C10: 2 | D10: 3 | E10: 4 | F10: 5 | G10: 6 | I10: 617 | J10: S2 | K10: b | L10: Luisa | M10: Tech 6 | N10: 2 | O10: 12 | P10: Tech 7 | Q10: 4 | R10: 11 | AB10: Tech 6 | AC10: 8 | AD10: 12 | AE10: 1 | AF10: 1 | AH10: Geraldin Salazar
A11: 6 | B11: =countifs(Students!$A:$A,$A11)-countifs(Students!$A:$A,$A11,Students!U:U,">0") -> 0 | C11: =countifs(Students!$A:$A,$A11)-countifs(Students!$A:$A,$A11,Students!V:V,">0") -> 0 | D11: =countifs(Students!$A:$A,$A11)-countifs(Students!$A:$A,$A11,Students!W:W,">0") -> 0 | E11: =countifs(Students!$A:$A,$A11)-countifs(Students!$A:$A,$A11,Students!X:X,">0") -> 0 | F11: =countifs(Students!$A:$A,$A11)-countifs(Students!$A:$A,$A11,Students!Y:Y,">0") -> 0 | G11: =countifs(Students!$A:$A,$A11)-countifs(Students!$A:$A,$A11,Students!Z:Z,">0") -> 0 | H11: =countifs(Students!A:A,A11)/6 -> 24 | I11: 328 | J11: S1 | K11: a | L11: Giovany | M11: Band 7 | N11: 1 | O11: 21 | P11: Band 8 | Q11: 2 | R11: 25 | Y11: Symphony Band | Z11: 1 | AA11: 26 | AB11: Regular Band | AC11: 1 | AD11: 23 | AE11: 1 | AH11: Giovany
A12: 7 | B12: =countifs(Students!$A:$A,$A12)-countifs(Students!$A:$A,$A12,Students!U:U,">0") -> 0 | C12: =countifs(Students!$A:$A,$A12)-countifs(Students!$A:$A,$A12,Students!V:V,">0") -> 0 | D12: =countifs(Students!$A:$A,$A12)-countifs(Students!$A:$A,$A12,Students!W:W,">0") -> 0 | E12: =countifs(Students!$A:$A,$A12)-countifs(Students!$A:$A,$A12,Students!X:X,">0") -> 0 | F12: =countifs(Students!$A:$A,$A12)-countifs(Students!$A:$A,$A12,Students!Y:Y,">0") -> 0 | G12: =countifs(Students!$A:$A,$A12)-countifs(Students!$A:$A,$A12,Students!Z:Z,">0") -> 0 | H12: =countifs(Students!A:A,A12)/6 -> 21.833333 | I12: 328 | J12: S1 | K12: b | L12: Giovany | M12: Band 8 | N12: 1 | O12: 25 | P12: Band 7 | Q12: 2 | R12: 22 | V12: Band 7 | W12: 3 | X12: 22 | Y12: Band 8 | Z12: 3 | AA12: 24 | AB12: Band 8 | AC12: 4 | AD12: 23 | AE12: 1 | AH12: John Jensen
A13: 8 | B13: =countifs(Students!$A:$A,$A13)-countifs(Students!$A:$A,$A13,Students!U:U,">0") -> 0 | C13: =countifs(Students!$A:$A,$A13)-countifs(Students!$A:$A,$A13,Students!V:V,">0") -> 0 | D13: =countifs(Students!$A:$A,$A13)-countifs(Students!$A:$A,$A13,Students!W:W,">0") -> 0 | E13: =countifs(Students!$A:$A,$A13)-countifs(Students!$A:$A,$A13,Students!X:X,">0") -> 0 | F13: =countifs(Students!$A:$A,$A13)-countifs(Students!$A:$A,$A13,Students!Y:Y,">0") -> 0 | G13: =countifs(Students!$A:$A,$A13)-countifs(Students!$A:$A,$A13,Students!Z:Z,">0") -> 0 | H13: =countifs(Students!A:A,A13)/6 -> 23.666667 | I13: 328 | J13: S2 | K13: a | L13: Giovany | M13: Band 7 | N13: 1 | O13: 21 | P13: Band 8 | Q13: 2 | R13: 25 | Y13: Symphony Band | Z13: 1 | AA13: 26 | AB13: Regular Band | AC13: 1 | AD13: 23 | AE13: 1 | AF13: 1 | AH13: Jordi Tur tur
I14: 328 | J14: S2 | K14: b | L14: Giovany | M14: Band 8 | N14: 1 | O14: 25 | P14: Band 7 | Q14: 2 | R14: 22 | V14: Band 7 | W14: 3 | X14: 22 | Y14: Band 8 | Z14: 3 | AA14: 24 | AB14: Band 8 | AC14: 4 | AD14: 23 | AF14: 1 | AH14: Joshua Vissers
I15: Cancha | K15: a | L15: Nando | M15: PE 8 | N15: 1 | O15: 25 | P15: PE 7 | Q15: 3 | R15: 22 | V15: PE 8 | W15: 3 | X15: 25 | Y15: PE 8 | Z15: 4 | AA15: 24 | AB15: PE 8 | AC15: 6 | AD15: 23 | AF15: 1 | AH15: Juan Pablo
I16: Cancha | K16: b | L16: Nando | M16: PE 7 | N16: 1 | O16: 21 | P16: PE 8 | Q16: 2 | R16: 25 | Y16: PE 8 | Z16: 5 | AA16: 20 | AB16: PE 7 | AC16: 6 | AD16: 23 | AE16: 1 | AH16: Luisa
I17: Coliseo | K17: a | L17: Juan Pablo | M17: PE 6 | N17: 1 | O17: 23 | P17: PE 7A | Q17: 4 | R17: 22 | V17: PE 7 | W17: 5 | X17: 22 | AB17: PE 6 | AC17: 5 | AD17: 24 | AE17: 1 | AH17: Manuela Castaño
I18: Coliseo | K18: b | L18: Juan Pablo | M18: PE 7A | N18: 2 | O18: 21 | P18: PE 6 | Q18: 2 | R18: 24 | V18: PE 6 | W18: 3 | X18: 24 | Y18: PE 6 | Z18: 4 | AA18: 26 | AB18: PE 6 | AC18: 6 | AD18: 23 | AG18: 1 | AH18: Mateo
I19: 611 | L19: Michael Landecker | M19: Math 6 | N19: 1 | O19: 24 | S19: Math 6 | T19: 2 | U19: 24 | Y19: Math 6A | Z19: 4 | AA19: 24 | AB19: Math 6 | AC19: 6 | AD19: 25 | AF19: 1 | AH19: Maxine McKinnon
I20: LC | L20: Mateo | M20: Math 8 | N20: 1 | O20: 21 | V20: Math 7 | W20: 3 | X20: 22 | Y20: Math 6A | Z20: 4 | AA20: 24 | AH20: Michael Landecker
I21: 612 | L21: Chris Matthews | S21: Math 7A | T21: 1 | U21: 23 | V21: Math 7 | W21: 3 | X21: 22 | Y21: Math 7 | Z21: 5 | AA21: 22 | AB21: Math 7 | AC21: 6 | AD21: 21 | AE21: 1 | AH21: Michael Ramires
I22: 621 | L22: Rachel McGarghan | M22: Math 8 | N22: 1 | O22: 21 | S22: Algebra | T22: 1 | U22: 25 | V22: Algebra | W22: 2 | X22: 25 | Y22: Algebra | Z22: 3 | AA22: 25 | AE22: 1 | AH22: Miguel Muñoz Ruiz
I23: 623 | L23: Taylor Nielson | M23: Math 8A | N23: 2 | O23: 24 | S23: Math 7 | T23: 2 | U23: 21 | V23: Math 7A | W23: 4 | X23: 22 | AB23: Math 8 | AC23: 3 | AD23: 22 | AF23: 1 | AH23: Nando
I24: 612 | L24: John Jensen | S24: Science 6 | T24: 2 | U24: 24 | V24: Math 6 | W24: 3 | X24: 24 | Y24: Math 6 | Z24: 5 | AA24: 23 | AB24: Science 6 | AC24: 6 | AD24: 24 | AG24: 1 | AH24: Nasli Vargas
L25: Ben Light | P25: Science 6 | Q25: 1 | R25: 24 | S25: Science 6A | T25: 3 | U25: 24 | V25: Science 6 | W25: 4 | X25: 24 | Y25: Science 6 | Z25: 5 | AA25: 24 | AH25: Rachel McGarghan
I26: 622 | L26: Sara DeAses | S26: Science 7 | T26: 2 | U26: 22 | V26: Science 7 | W26: 3 | X26: 23 | Y26: Science 7 | Z26: 4 | AA26: 21 | AB26: Science 7 | AC26: 5 | AD26: 22 | AH26: Sara DeAses
L27: Michael Ramires | P27: Science 8 | Q27: 1 | R27: 23 | S27: Science 8 | T27: 2 | U27: 25 | V27: Science 8A | W27: 4 | X27: 21 | AB27: Science 8 | AC27: 6 | AD27: 25 | AH27: Sebastian Guerra Cifuentes
I28: 632 | L28: Miguel Muñoz Ruiz | P28: Science 7 | Q28: 1 | R28: 21 | V28: Science 8 | W28: 3 | X28: 23 | Y28: Science 8 | Z28: 5 | AA28: 25 | AB28: Science 7A | AC28: 6 | AD28: 22 | AH28: Shaila Raen Nicholson
I29: 623 | L29: Maxine McKinnon | M29: English 6A | N29: 1 | O29: 24 | P29: English 6 | Q29: 3 | R29: 24 | S29: English 6 | T29: 4 | U29: 24 | AB29: English 6 | AC29: 6 | AD29: 24 | AE29: 1 | AG29: 1 | AH29: Taylor Nielson
I30: LC | L30: Viviana | M30: English 6A | N30: 1 | O30: 24 | Y30: English 7 | Z30: 4 | AA30: 22 | AB30: English 8 | AC30: 5 | AD30: 23 | AH30: Vicente Miralles
I31: 616 | L31: Brandon Berry | M31: English 6 | N31: 2 | O31: 25 | S31: English 8 | T31: 3 | U31: 25 | Y31: English 6 | Z31: 5 | AA31: 23 | AB31: English 8A | AC31: 6 | AD31: 24 | AE31: 1 | AG31: 1 | AH31: Viviana
I32: 625 | L32: Jordi Tur tur | M32: English 7 | N32: 1 | O32: 23 | S32: English 7 | T32: 3 | U32: 21 | Y32: English 7A | Z32: 5 | AA32: 22 | AB32: English 7 | AC32: 6 | AD32: 21 | AF32: 1 | AG32: 1 | AH32: William Duque
I33: 635 | L33: Shaila Raen Nicholson | M33: English 8 | N33: 1 | O33: 22 | P33: English 8 | Q33: 2 | R33: 25 | Y33: English 8 | Z33: 4 | AA33: 23 | AB33: English 8 | AC33: 5 | AD33: 23 | AF33: 1
I34: 627 | L34: Andrea Gil | M34: Sociales 8 | N34: 1 | O34: 25 | P34: English 7 | Q34: 2 | R34: 22 | S34: Sociales 8A | T34: 4 | U34: 21 | Y34: English 7 | Z34: 4 | AA34: 22 | AE34: 1
I35: 637 | L35: Joshua Vissers | P35: Sociales 8 | Q35: 2 | R35: 25 | S35: Sociales 8 | T35: 3 | U35: 23 | V35: Sociales 8 | W35: 5 | X35: 23 | Y35: Sociales 8 | Z35: 6 | AA35: 25
I36: 614 | L36: Sebastian Guerra Cifuentes | M36: Sociales 6 | N36: 1 | O36: 24 | P36: Sociales 6 | Q36: 2 | R36: 24 | V36: Sociales 6 | W36: 5 | X36: 24 | Y36: Sociales 6 | Z36: 6 | AA36: 24
L37: Nasli Vargas | M37: Sociales 7A | N37: 1 | O37: 22 | P37: Sociales 6A | Q37: 3 | R37: 24 | S37: Sociales 6 | T37: 4 | U37: 24 | Y37: Sociales 7A | Z37: 5 | AA37: 22
I38: 631 | L38: William Duque | M38: Sociales 7 | N38: 2 | O38: 22 | P38: Sociales 7 | Q38: 3 | R38: 21 | S38: Sociales 7 | T38: 4 | U38: 22 | Y38: Sociales 7 | Z38: 6 | AA38: 22
I39: 615 | L39: Geraldin Salazar | M39: Spanish 6 | N39: 1 | O39: 24 | P39: Spanish 6 | Q39: 2 | R39: 19 | S39: Spanish 6 | T39: 3 | U39: 24 | V39: Spanish 6 | W39: 4 | X39: 24
I40: 615 | L40: Vicente Miralles | P40: SAL | Q40: 1 | R40: 7 | V40: Spanish 6A | W40: 5 | X40: 24 | AB40: Spanish 6 | AC40: 6 | AD40: 24
...

Sheet Student Groupings
A1: {=if(ROW(A:A)=1,"Código",if(E:E="","",row(A:A)-1))} -> Código | B1: First Student | C1: {=if(ROW(C:C)=1,"ID",if(B:B="","",xlookup(B:B,Students!C:C,Students!B:B)))} -> ID | D1: {=if(ROW(D:D)=1,"Grade next year (automated)",if(B:B="","",vlookup(B:B,{Students!$C:$C,Students!$A:$A},2,false)))} -> Grade next year (automated) | E1: Second Student | F1: {=if(ROW(C:C)=1,"ID",if(E:E="","",xlookup(E:E,Students!C:C,Students!B:B)))} -> ID | G1: {=if(ROW(G:G)=1,"Grade next year (automated)",if(E:E="","",vlookup(E:E,{Students!$C:$C,Students!$A:$A},2,false)))} -> Grade next year (automated) | H1: Relationship | I1: Grupos juntos (todos) | J1: Grupos juntos con mAs de 1 secciOn disponible | K1: Cursos que comparten | L1: =IFERROR(__xludf.DUMMYFUNCTION("unique(filter({filter('Students (Vertical)'!O:O,'Students (Vertical)'!C:C=B6,'Students (Vertical)'!O:O<>"""",'Students (Vertical)'!P:P>1);filter('Students (Vertical)'!O:O,'Students (Vertical)'!C:C=E6,'Students (Vertical)'!O:O<>"""",'Students (Vertical)'!P"&":P>1)},countifs({filter('Students (Vertical)'!O:O,'Students (Vertical)'!C:C=B6,'Students (Vertical)'!O:O<>"""",'Students (Vertical)'!P:P>1);filter('Students (Vertical)'!O:O,'Students (Vertical)'!C:C=E6,'Students (Vertical)'!O:O<>"""",'Students (Vertical)'"&"!P:P>1)},{filter('Students (Vertical)'!O:O,'Students (Vertical)'!C:C=B6,'Students (Vertical)'!O:O<>"""",'Students (Vertical)'!P:P>1);filter('Students (Vertical)'!O:O,'Students (Vertical)'!C:C=E6,'Students (Vertical)'!O:O<>"""",'Students (Vertical)'!P:P>1)"&"})>1))"),"Science 6-2") -> Science 6-2
A2: 1 | B2: URRETA HENAO, PEDRO | C2: 31128 | D2: 6 | E2: ZULUAGA HOYOS, ALEJANDRO | F2: 31137 | G2: 6 | H2: Can't be Together | I2: =IFERROR(__xludf.DUMMYFUNCTION("if(H2=""Must be Together"",iferror(join("", "",unique(filter({filter('Students (Vertical)'!O:O,'Students (Vertical)'!C:C=B2,'Students (Vertical)'!O:O<>"""");filter('Students (Vertical)'!O:O,'Students (Vertical)'!C:C=E2,'Students (Vertical)'!O:O<>"""")},co"&"untifs({filter('Students (Vertical)'!O:O,'Students (Vertical)'!C:C=B2,'Students (Vertical)'!O:O<>"""");filter('Students (Vertical)'!O:O,'Students (Vertical)'!C:C=E2,'Students (Vertical)'!O:O<>"""")},{filter('Students (Vertical)'!O:O,'Students (Vertical)'!"&"C:C=B2,'Students (Vertical)'!O:O<>"""");filter('Students (Vertical)'!O:O,'Students (Vertical)'!C:C=E2,'Students (Vertical)'!O:O<>"""")})>1))),""No shared courses""),"""")"),"") | J2: =IFERROR(__xludf.DUMMYFUNCTION("if(H2=""Can't be Together"",iferror(join("", "",unique(filter({unique(filter('Students (Vertical)'!O:O,'Students (Vertical)'!C:C=B2,'Students (Vertical)'!O:O<>"""",'Students (Vertical)'!P:P>1));unique(filter('Students (Vertical)'!O:O,'Students (Vertical)'"&"!C:C=E2,'Students (Vertical)'!O:O<>"""",'Students (Vertical)'!P:P>1))},countifs({unique(filter('Students (Vertical)'!O:O,'Students (Vertical)'!C:C=B2,'Students (Vertical)'!O:O<>"""",'Students (Vertical)'!P:P>1));unique(filter('Students (Vertical)'!O:O,'St"&"udents (Vertical)'!C:C=E2,'Students (Vertical)'!O:O<>"""",'Students (Vertical)'!P:P>1))},{unique(filter('Students (Vertical)'!O:O,'Students (Vertical)'!C:C=B2,'Students (Vertical)'!O:O<>"""",'Students (Vertical)'!P:P>1));unique(filter('Students (Vertical)"&"'!O:O,'Students (Vertical)'!C:C=E2,'Students (Vertical)'!O:O<>"""",'Students (Vertical)'!P:P>1))})>1))),""""),"""")"),"PE 6-6b") -> PE 6-6b | K2: =IFERROR(__xludf.DUMMYFUNCTION("iferror(join("", "",unique(filter({filter('Students (Vertical)'!D:D,'Students (Vertical)'!C:C=B2,'Students (Vertical)'!D:D<>"""");filter('Students (Vertical)'!D:D,'Students (Vertical)'!C:C=E2,'Students (Vertical)'!D:D<>"""")},countifs({filter('Students (V"&"ertical)'!D:D,'Students (Vertical)'!C:C=B2,'Students (Vertical)'!D:D<>"""");filter('Students (Vertical)'!D:D,'Students (Vertical)'!C:C=E2,'Students (Vertical)'!D:D<>"""")},{filter('Students (Vertical)'!D:D,'Students (Vertical)'!C:C=B2,'Students (Vertical)"&"'!D:D<>"""");filter('Students (Vertical)'!D:D,'Students (Vertical)'!C:C=E2,'Students (Vertical)'!D:D<>"""")})>1))),"""")"),"Science 6, Sociales 6, Spanish 6, PE 6, Regular BandS1, Regular BandS2") -> Science 6, Sociales 6, Spanish 6, PE 6, Regular BandS1, Regular BandS2 | L2: =IFERROR(__xludf.DUMMYFUNCTION("""COMPUTED_VALUE"""),"English 6-6") -> English 6-6
A3: 2 | B3: URRETA HENAO, PEDRO | C3: 31128 | D3: 6 | E3: TORO PEREZ, GREGORIO | F3: 31120 | G3: 6 | H3: Must be Together | I3: =IFERROR(__xludf.DUMMYFUNCTION("if(H3=""Must be Together"",iferror(join("", "",unique(filter({filter('Students (Vertical)'!O:O,'Students (Vertical)'!C:C=B3,'Students (Vertical)'!O:O<>"""");filter('Students (Vertical)'!O:O,'Students (Vertical)'!C:C=E3,'Students (Vertical)'!O:O<>"""")},co"&"untifs({filter('Students (Vertical)'!O:O,'Students (Vertical)'!C:C=B3,'Students (Vertical)'!O:O<>"""");filter('Students (Vertical)'!O:O,'Students (Vertical)'!C:C=E3,'Students (Vertical)'!O:O<>"""")},{filter('Students (Vertical)'!O:O,'Students (Vertical)'!"&"C:C=B3,'Students (Vertical)'!O:O<>"""");filter('Students (Vertical)'!O:O,'Students (Vertical)'!C:C=E3,'Students (Vertical)'!O:O<>"""")})>1))),""No shared courses""),"""")"),"Science 6-4, Math 6A-5, Sociales 6-3, Spanish 6-2") -> Science 6-4, Math 6A-5, Sociales 6-3, Spanish 6-2 | J3: =IFERROR(__xludf.DUMMYFUNCTION("if(H3=""Can't be Together"",iferror(join("", "",unique(filter({unique(filter('Students (Vertical)'!O:O,'Students (Vertical)'!C:C=B3,'Students (Vertical)'!O:O<>"""",'Students (Vertical)'!P:P>1));unique(filter('Students (Vertical)'!O:O,'Students (Vertical)'"&"!C:C=E3,'Students (Vertical)'!O:O<>"""",'Students (Vertical)'!P:P>1))},countifs({unique(filter('Students (Vertical)'!O:O,'Students (Vertical)'!C:C=B3,'Students (Vertical)'!O:O<>"""",'Students (Vertical)'!P:P>1));unique(filter('Students (Vertical)'!O:O,'St"&"udents (Vertical)'!C:C=E3,'Students (Vertical)'!O:O<>"""",'Students (Vertical)'!P:P>1))},{unique(filter('Students (Vertical)'!O:O,'Students (Vertical)'!C:C=B3,'Students (Vertical)'!O:O<>"""",'Students (Vertical)'!P:P>1));unique(filter('Students (Vertical)"&"'!O:O,'Students (Vertical)'!C:C=E3,'Students (Vertical)'!O:O<>"""",'Students (Vertical)'!P:P>1))})>1))),""""),"""")"),"") | K3: =IFERROR(__xludf.DUMMYFUNCTION("iferror(join("", "",unique(filter({filter('Students (Vertical)'!D:D,'Students (Vertical)'!C:C=B3,'Students (Vertical)'!D:D<>"""");filter('Students (Vertical)'!D:D,'Students (Vertical)'!C:C=E3,'Students (Vertical)'!D:D<>"""")},countifs({filter('Students (V"&"ertical)'!D:D,'Students (Vertical)'!C:C=B3,'Students (Vertical)'!D:D<>"""");filter('Students (Vertical)'!D:D,'Students (Vertical)'!C:C=E3,'Students (Vertical)'!D:D<>"""")},{filter('Students (Vertical)'!D:D,'Students (Vertical)'!C:C=B3,'Students (Vertical)"&"'!D:D<>"""");filter('Students (Vertical)'!D:D,'Students (Vertical)'!C:C=E3,'Students (Vertical)'!D:D<>"""")})>1))),"""")"),"Science 6, Math 6A, Sociales 6, Spanish 6, PE 6") -> Science 6, Math 6A, Sociales 6, Spanish 6, PE 6 | L3: =IFERROR(__xludf.DUMMYFUNCTION("""COMPUTED_VALUE"""),"Sociales 6-4") -> Sociales 6-4
A4: 3 | B4: URRETA HENAO, PEDRO | C4: 31128 | D4: 6 | E4: REPETTO LARROSA, FRANCHESCO | F4: 31173 | G4: 6 | H4: Must be Together | I4: =IFERROR(__xludf.DUMMYFUNCTION("if(H4=""Must be Together"",iferror(join("", "",unique(filter({filter('Students (Vertical)'!O:O,'Students (Vertical)'!C:C=B4,'Students (Vertical)'!O:O<>"""");filter('Students (Vertical)'!O:O,'Students (Vertical)'!C:C=E4,'Students (Vertical)'!O:O<>"""")},co"&"untifs({filter('Students (Vertical)'!O:O,'Students (Vertical)'!C:C=B4,'Students (Vertical)'!O:O<>"""");filter('Students (Vertical)'!O:O,'Students (Vertical)'!C:C=E4,'Students (Vertical)'!O:O<>"""")},{filter('Students (Vertical)'!O:O,'Students (Vertical)'!"&"C:C=B4,'Students (Vertical)'!O:O<>"""");filter('Students (Vertical)'!O:O,'Students (Vertical)'!C:C=E4,'Students (Vertical)'!O:O<>"""")})>1))),""No shared courses""),"""")"),"Science 6-4, Math 6A-5, English 6A-1, Sociales 6-3, Spanish 6-2") -> Science 6-4, Math 6A-5, English 6A-1, Sociales 6-3, Spanish 6-2 | J4: =IFERROR(__xludf.DUMMYFUNCTION("if(H4=""Can't be Together"",iferror(join("", "",unique(filter({unique(filter('Students (Vertical)'!O:O,'Students (Vertical)'!C:C=B4,'Students (Vertical)'!O:O<>"""",'Students (Vertical)'!P:P>1));unique(filter('Students (Vertical)'!O:O,'Students (Vertical)'"&"!C:C=E4,'Students (Vertical)'!O:O<>"""",'Students (Vertical)'!P:P>1))},countifs({unique(filter('Students (Vertical)'!O:O,'Students (Vertical)'!C:C=B4,'Students (Vertical)'!O:O<>"""",'Students (Vertical)'!P:P>1));unique(filter('Students (Vertical)'!O:O,'St"&"udents (Vertical)'!C:C=E4,'Students (Vertical)'!O:O<>"""",'Students (Vertical)'!P:P>1))},{unique(filter('Students (Vertical)'!O:O,'Students (Vertical)'!C:C=B4,'Students (Vertical)'!O:O<>"""",'Students (Vertical)'!P:P>1));unique(filter('Students (Vertical)"&"'!O:O,'Students (Vertical)'!C:C=E4,'Students (Vertical)'!O:O<>"""",'Students (Vertical)'!P:P>1))})>1))),""""),"""")"),"") | K4: =IFERROR(__xludf.DUMMYFUNCTION("iferror(join("", "",unique(filter({filter('Students (Vertical)'!D:D,'Students (Vertical)'!C:C=B4,'Students (Vertical)'!D:D<>"""");filter('Students (Vertical)'!D:D,'Students (Vertical)'!C:C=E4,'Students (Vertical)'!D:D<>"""")},countifs({filter('Students (V"&"ertical)'!D:D,'Students (Vertical)'!C:C=B4,'Students (Vertical)'!D:D<>"""");filter('Students (Vertical)'!D:D,'Students (Vertical)'!C:C=E4,'Students (Vertical)'!D:D<>"""")},{filter('Students (Vertical)'!D:D,'Students (Vertical)'!C:C=B4,'Students (Vertical)"&"'!D:D<>"""");filter('Students (Vertical)'!D:D,'Students (Vertical)'!C:C=E4,'Students (Vertical)'!D:D<>"""")})>1))),"""")"),"Science 6, Math 6A, English 6A, Sociales 6, Spanish 6, PE 6") -> Science 6, Math 6A, English 6A, Sociales 6, Spanish 6, PE 6 | L4: =IFERROR(__xludf.DUMMYFUNCTION("""COMPUTED_VALUE"""),"Spanish 6-3") -> Spanish 6-3
A5: 4 | B5: BORDA AZCARATE, AGUSTIN | C5: 31017 | D5: 6 | E5: MEJIA GALLEGO, MARTIN | F5: 31070 | G5: 6 | H5: Can't be Together | I5: =IFERROR(__xludf.DUMMYFUNCTION("if(H5=""Must be Together"",iferror(join("", "",unique(filter({filter('Students (Vertical)'!O:O,'Students (Vertical)'!C:C=B5,'Students (Vertical)'!O:O<>"""");filter('Students (Vertical)'!O:O,'Students (Vertical)'!C:C=E5,'Students (Vertical)'!O:O<>"""")},co"&"untifs({filter('Students (Vertical)'!O:O,'Students (Vertical)'!C:C=B5,'Students (Vertical)'!O:O<>"""");filter('Students (Vertical)'!O:O,'Students (Vertical)'!C:C=E5,'Students (Vertical)'!O:O<>"""")},{filter('Students (Vertical)'!O:O,'Students (Vertical)'!"&"C:C=B5,'Students (Vertical)'!O:O<>"""");filter('Students (Vertical)'!O:O,'Students (Vertical)'!C:C=E5,'Students (Vertical)'!O:O<>"""")})>1))),""No shared courses""),"""")"),"") | J5: =IFERROR(__xludf.DUMMYFUNCTION("if(H5=""Can't be Together"",iferror(join("", "",unique(filter({unique(filter('Students (Vertical)'!O:O,'Students (Vertical)'!C:C=B5,'Students (Vertical)'!O:O<>"""",'Students (Vertical)'!P:P>1));unique(filter('Students (Vertical)'!O:O,'Students (Vertical)'"&"!C:C=E5,'Students (Vertical)'!O:O<>"""",'Students (Vertical)'!P:P>1))},countifs({unique(filter('Students (Vertical)'!O:O,'Students (Vertical)'!C:C=B5,'Students (Vertical)'!O:O<>"""",'Students (Vertical)'!P:P>1));unique(filter('Students (Vertical)'!O:O,'St"&"udents (Vertical)'!C:C=E5,'Students (Vertical)'!O:O<>"""",'Students (Vertical)'!P:P>1))},{unique(filter('Students (Vertical)'!O:O,'Students (Vertical)'!C:C=B5,'Students (Vertical)'!O:O<>"""",'Students (Vertical)'!P:P>1));unique(filter('Students (Vertical)"&"'!O:O,'Students (Vertical)'!C:C=E5,'Students (Vertical)'!O:O<>"""",'Students (Vertical)'!P:P>1))})>1))),""""),"""")"),"PE 6-5b") -> PE 6-5b | K5: =IFERROR(__xludf.DUMMYFUNCTION("iferror(join("", "",unique(filter({filter('Students (Vertical)'!D:D,'Students (Vertical)'!C:C=B5,'Students (Vertical)'!D:D<>"""");filter('Students (Vertical)'!D:D,'Students (Vertical)'!C:C=E5,'Students (Vertical)'!D:D<>"""")},countifs({filter('Students (V"&"ertical)'!D:D,'Students (Vertical)'!C:C=B5,'Students (Vertical)'!D:D<>"""");filter('Students (Vertical)'!D:D,'Students (Vertical)'!C:C=E5,'Students (Vertical)'!D:D<>"""")},{filter('Students (Vertical)'!D:D,'Students (Vertical)'!C:C=B5,'Students (Vertical)"&"'!D:D<>"""");filter('Students (Vertical)'!D:D,'Students (Vertical)'!C:C=E5,'Students (Vertical)'!D:D<>"""")})>1))),"""")"),"Science 6, Math 6, English 6, Sociales 6, Spanish 6, PE 6, Symphony BandS1, Symphony BandS2") -> Science 6, Math 6, English 6, Sociales 6, Spanish 6, PE 6, Symphony BandS1, Symphony BandS2 | L5: =IFERROR(__xludf.DUMMYFUNCTION("""COMPUTED_VALUE"""),"PE 6-1a") -> PE 6-1a
A6: 5 | B6: VELEZ ARANGO, LAURA | C6: 31134 | D6: 6 | E6: JONCK CORRENTE, CLARICE | F6: 31172 | G6: 6 | H6: Must be Together | I6: =IFERROR(__xludf.DUMMYFUNCTION("if(H6=""Must be Together"",iferror(join("", "",unique(filter({filter('Students (Vertical)'!O:O,'Students (Vertical)'!C:C=B6,'Students (Vertical)'!O:O<>"""");filter('Students (Vertical)'!O:O,'Students (Vertical)'!C:C=E6,'Students (Vertical)'!O:O<>"""")},co"&"untifs({filter('Students (Vertical)'!O:O,'Students (Vertical)'!C:C=B6,'Students (Vertical)'!O:O<>"""");filter('Students (Vertical)'!O:O,'Students (Vertical)'!C:C=E6,'Students (Vertical)'!O:O<>"""")},{filter('Students (Vertical)'!O:O,'Students (Vertical)'!"&"C:C=B6,'Students (Vertical)'!O:O<>"""");filter('Students (Vertical)'!O:O,'Students (Vertical)'!C:C=E6,'Students (Vertical)'!O:O<>"""")})>1))),""No shared courses""),"""")"),"Science 6-2, English 6-6, Sociales 6-4, Spanish 6-3, PE 6-1a, Art 6S1-1b, Tech 6S2-1b") -> Science 6-2, English 6-6, Sociales 6-4, Spanish 6-3, PE 6-1a, Art 6S1-1b, Tech 6S2-1b | J6: =IFERROR(__xludf.DUMMYFUNCTION("if(H6=""Can't be Together"",iferror(join("", "",unique(filter({unique(filter('Students (Vertical)'!O:O,'Students (Vertical)'!C:C=B6,'Students (Vertical)'!O:O<>"""",'Students (Vertical)'!P:P>1));unique(filter('Students (Vertical)'!O:O,'Students (Vertical)'"&"!C:C=E6,'Students (Vertical)'!O:O<>"""",'Students (Vertical)'!P:P>1))},countifs({unique(filter('Students (Vertical)'!O:O,'Students (Vertical)'!C:C=B6,'Students (Vertical)'!O:O<>"""",'Students (Vertical)'!P:P>1));unique(filter('Students (Vertical)'!O:O,'St"&"udents (Vertical)'!C:C=E6,'Students (Vertical)'!O:O<>"""",'Students (Vertical)'!P:P>1))},{unique(filter('Students (Vertical)'!O:O,'Students (Vertical)'!C:C=B6,'Students (Vertical)'!O:O<>"""",'Students (Vertical)'!P:P>1));unique(filter('Students (Vertical)"&"'!O:O,'Students (Vertical)'!C:C=E6,'Students (Vertical)'!O:O<>"""",'Students (Vertical)'!P:P>1))})>1))),""""),"""")"),"") | K6: =IFERROR(__xludf.DUMMYFUNCTION("iferror(join("", "",unique(filter({filter('Students (Vertical)'!D:D,'Students (Vertical)'!C:C=B6,'Students (Vertical)'!D:D<>"""");filter('Students (Vertical)'!D:D,'Students (Vertical)'!C:C=E6,'Students (Vertical)'!D:D<>"""")},countifs({filter('Students (V"&"ertical)'!D:D,'Students (Vertical)'!C:C=B6,'Students (Vertical)'!D:D<>"""");filter('Students (Vertical)'!D:D,'Students (Vertical)'!C:C=E6,'Students (Vertical)'!D:D<>"""")},{filter('Students (Vertical)'!D:D,'Students (Vertical)'!C:C=B6,'Students (Vertical)"&"'!D:D<>"""");filter('Students (Vertical)'!D:D,'Students (Vertical)'!C:C=E6,'Students (Vertical)'!D:D<>"""")})>1))),"""")"),"Science 6, English 6, Sociales 6, Spanish 6, PE 6, Art 6S1, Tech 6S2") -> Science 6, English 6, Sociales 6, Spanish 6, PE 6, Art 6S1, Tech 6S2
A7: 6 | B7: VELEZ ARANGO, LAURA | C7: 31134 | D7: 6 | E7: RESTREPO PELAEZ, EMILIA | F7: 31105 | G7: 6 | H7: Can't be Together | I7: =IFERROR(__xludf.DUMMYFUNCTION("if(H7=""Must be Together"",iferror(join("", "",unique(filter({filter('Students (Vertical)'!O:O,'Students (Vertical)'!C:C=B7,'Students (Vertical)'!O:O<>"""");filter('Students (Vertical)'!O:O,'Students (Vertical)'!C:C=E7,'Students (Vertical)'!O:O<>"""")},co"&"untifs({filter('Students (Vertical)'!O:O,'Students (Vertical)'!C:C=B7,'Students (Vertical)'!O:O<>"""");filter('Students (Vertical)'!O:O,'Students (Vertical)'!C:C=E7,'Students (Vertical)'!O:O<>"""")},{filter('Students (Vertical)'!O:O,'Students (Vertical)'!"&"C:C=B7,'Students (Vertical)'!O:O<>"""");filter('Students (Vertical)'!O:O,'Students (Vertical)'!C:C=E7,'Students (Vertical)'!O:O<>"""")})>1))),""No shared courses""),"""")"),"") | J7: =IFERROR(__xludf.DUMMYFUNCTION("if(H7=""Can't be Together"",iferror(join("", "",unique(filter({unique(filter('Students (Vertical)'!O:O,'Students (Vertical)'!C:C=B7,'Students (Vertical)'!O:O<>"""",'Students (Vertical)'!P:P>1));unique(filter('Students (Vertical)'!O:O,'Students (Vertical)'"&"!C:C=E7,'Students (Vertical)'!O:O<>"""",'Students (Vertical)'!P:P>1))},countifs({unique(filter('Students (Vertical)'!O:O,'Students (Vertical)'!C:C=B7,'Students (Vertical)'!O:O<>"""",'Students (Vertical)'!P:P>1));unique(filter('Students (Vertical)'!O:O,'St"&"udents (Vertical)'!C:C=E7,'Students (Vertical)'!O:O<>"""",'Students (Vertical)'!P:P>1))},{unique(filter('Students (Vertical)'!O:O,'Students (Vertical)'!C:C=B7,'Students (Vertical)'!O:O<>"""",'Students (Vertical)'!P:P>1));unique(filter('Students (Vertical)"&"'!O:O,'Students (Vertical)'!C:C=E7,'Students (Vertical)'!O:O<>"""",'Students (Vertical)'!P:P>1))})>1))),""""),"""")"),"") | K7: =IFERROR(__xludf.DUMMYFUNCTION("iferror(join("", "",unique(filter({filter('Students (Vertical)'!D:D,'Students (Vertical)'!C:C=B7,'Students (Vertical)'!D:D<>"""");filter('Students (Vertical)'!D:D,'Students (Vertical)'!C:C=E7,'Students (Vertical)'!D:D<>"""")},countifs({filter('Students (V"&"ertical)'!D:D,'Students (Vertical)'!C:C=B7,'Students (Vertical)'!D:D<>"""");filter('Students (Vertical)'!D:D,'Students (Vertical)'!C:C=E7,'Students (Vertical)'!D:D<>"""")},{filter('Students (Vertical)'!D:D,'Students (Vertical)'!C:C=B7,'Students (Vertical)"&"'!D:D<>"""");filter('Students (Vertical)'!D:D,'Students (Vertical)'!C:C=E7,'Students (Vertical)'!D:D<>"""")})>1))),"""")"),"Science 6, English 6, Sociales 6, Spanish 6, PE 6, Art 6S1, Tech 6S2") -> Science 6, English 6, Sociales 6, Spanish 6, PE 6, Art 6S1, Tech 6S2
A8: 7 | B8: VELEZ ARANGO, LAURA | C8: 31134 | D8: 6 | E8: BOTERO BOTERO, AMALIA | F8: 31019 | G8: 6 | H8: Can't be Together | I8: =IFERROR(__xludf.DUMMYFUNCTION("if(H8=""Must be Together"",iferror(join("", "",unique(filter({filter('Students (Vertical)'!O:O,'Students (Vertical)'!C:C=B8,'Students (Vertical)'!O:O<>"""");filter('Students (Vertical)'!O:O,'Students (Vertical)'!C:C=E8,'Students (Vertical)'!O:O<>"""")},co"&"untifs({filter('Students (Vertical)'!O:O,'Students (Vertical)'!C:C=B8,'Students (Vertical)'!O:O<>"""");filter('Students (Vertical)'!O:O,'Students (Vertical)'!C:C=E8,'Students (Vertical)'!O:O<>"""")},{filter('Students (Vertical)'!O:O,'Students (Vertical)'!"&"C:C=B8,'Students (Vertical)'!O:O<>"""");filter('Students (Vertical)'!O:O,'Students (Vertical)'!C:C=E8,'Students (Vertical)'!O:O<>"""")})>1))),""No shared courses""),"""")"),"") | J8: =IFERROR(__xludf.DUMMYFUNCTION("if(H8=""Can't be Together"",iferror(join("", "",unique(filter({unique(filter('Students (Vertical)'!O:O,'Students (Vertical)'!C:C=B8,'Students (Vertical)'!O:O<>"""",'Students (Vertical)'!P:P>1));unique(filter('Students (Vertical)'!O:O,'Students (Vertical)'"&"!C:C=E8,'Students (Vertical)'!O:O<>"""",'Students (Vertical)'!P:P>1))},countifs({unique(filter('Students (Vertical)'!O:O,'Students (Vertical)'!C:C=B8,'Students (Vertical)'!O:O<>"""",'Students (Vertical)'!P:P>1));unique(filter('Students (Vertical)'!O:O,'St"&"udents (Vertical)'!C:C=E8,'Students (Vertical)'!O:O<>"""",'Students (Vertical)'!P:P>1))},{unique(filter('Students (Vertical)'!O:O,'Students (Vertical)'!C:C=B8,'Students (Vertical)'!O:O<>"""",'Students (Vertical)'!P:P>1));unique(filter('Students (Vertical)"&"'!O:O,'Students (Vertical)'!C:C=E8,'Students (Vertical)'!O:O<>"""",'Students (Vertical)'!P:P>1))})>1))),""""),"""")"),"") | K8: =IFERROR(__xludf.DUMMYFUNCTION("iferror(join("", "",unique(filter({filter('Students (Vertical)'!D:D,'Students (Vertical)'!C:C=B8,'Students (Vertical)'!D:D<>"""");filter('Students (Vertical)'!D:D,'Students (Vertical)'!C:C=E8,'Students (Vertical)'!D:D<>"""")},countifs({filter('Students (V"&"ertical)'!D:D,'Students (Vertical)'!C:C=B8,'Students (Vertical)'!D:D<>"""");filter('Students (Vertical)'!D:D,'Students (Vertical)'!C:C=E8,'Students (Vertical)'!D:D<>"""")},{filter('Students (Vertical)'!D:D,'Students (Vertical)'!C:C=B8,'Students (Vertical)"&"'!D:D<>"""");filter('Students (Vertical)'!D:D,'Students (Vertical)'!C:C=E8,'Students (Vertical)'!D:D<>"""")})>1))),"""")"),"Science 6, English 6, Sociales 6, Spanish 6, PE 6, Art 6S1, Tech 6S2") -> Science 6, English 6, Sociales 6, Spanish 6, PE 6, Art 6S1, Tech 6S2
A9: 8 | B9: VELEZ ARANGO, LAURA | C9: 31134 | D9: 6 | E9: ALVAREZ RIVERA, SALVADOR | F9: 31004 | G9: 6 | H9: Can't be Together | I9: =IFERROR(__xludf.DUMMYFUNCTION("if(H9=""Must be Together"",iferror(join("", "",unique(filter({filter('Students (Vertical)'!O:O,'Students (Vertical)'!C:C=B9,'Students (Vertical)'!O:O<>"""");filter('Students (Vertical)'!O:O,'Students (Vertical)'!C:C=E9,'Students (Vertical)'!O:O<>"""")},co"&"untifs({filter('Students (Vertical)'!O:O,'Students (Vertical)'!C:C=B9,'Students (Vertical)'!O:O<>"""");filter('Students (Vertical)'!O:O,'Students (Vertical)'!C:C=E9,'Students (Vertical)'!O:O<>"""")},{filter('Students (Vertical)'!O:O,'Students (Vertical)'!"&"C:C=B9,'Students (Vertical)'!O:O<>"""");filter('Students (Vertical)'!O:O,'Students (Vertical)'!C:C=E9,'Students (Vertical)'!O:O<>"""")})>1))),""No shared courses""),"""")"),"") | J9: =IFERROR(__xludf.DUMMYFUNCTION("if(H9=""Can't be Together"",iferror(join("", "",unique(filter({unique(filter('Students (Vertical)'!O:O,'Students (Vertical)'!C:C=B9,'Students (Vertical)'!O:O<>"""",'Students (Vertical)'!P:P>1));unique(filter('Students (Vertical)'!O:O,'Students (Vertical)'"&"!C:C=E9,'Students (Vertical)'!O:O<>"""",'Students (Vertical)'!P:P>1))},countifs({unique(filter('Students (Vertical)'!O:O,'Students (Vertical)'!C:C=B9,'Students (Vertical)'!O:O<>"""",'Students (Vertical)'!P:P>1));unique(filter('Students (Vertical)'!O:O,'St"&"udents (Vertical)'!C:C=E9,'Students (Vertical)'!O:O<>"""",'Students (Vertical)'!P:P>1))},{unique(filter('Students (Vertical)'!O:O,'Students (Vertical)'!C:C=B9,'Students (Vertical)'!O:O<>"""",'Students (Vertical)'!P:P>1));unique(filter('Students (Vertical)"&"'!O:O,'Students (Vertical)'!C:C=E9,'Students (Vertical)'!O:O<>"""",'Students (Vertical)'!P:P>1))})>1))),""""),"""")"),"") | K9: =IFERROR(__xludf.DUMMYFUNCTION("iferror(join("", "",unique(filter({filter('Students (Vertical)'!D:D,'Students (Vertical)'!C:C=B9,'Students (Vertical)'!D:D<>"""");filter('Students (Vertical)'!D:D,'Students (Vertical)'!C:C=E9,'Students (Vertical)'!D:D<>"""")},countifs({filter('Students (V"&"ertical)'!D:D,'Students (Vertical)'!C:C=B9,'Students (Vertical)'!D:D<>"""");filter('Students (Vertical)'!D:D,'Students (Vertical)'!C:C=E9,'Students (Vertical)'!D:D<>"""")},{filter('Students (Vertical)'!D:D,'Students (Vertical)'!C:C=B9,'Students (Vertical)"&"'!D:D<>"""");filter('Students (Vertical)'!D:D,'Students (Vertical)'!C:C=E9,'Students (Vertical)'!D:D<>"""")})>1))),"""")"),"Science 6, English 6, Sociales 6, Spanish 6, PE 6") -> Science 6, English 6, Sociales 6, Spanish 6, PE 6
A10: 9 | B10: VELEZ ARANGO, LAURA | C10: 31134 | D10: 6 | E10: PELAEZ BOTERO, AMELIA | F10: 31088 | G10: 6 | H10: Can't be Together | I10: =IFERROR(__xludf.DUMMYFUNCTION("if(H10=""Must be Together"",iferror(join("", "",unique(filter({filter('Students (Vertical)'!O:O,'Students (Vertical)'!C:C=B10,'Students (Vertical)'!O:O<>"""");filter('Students (Vertical)'!O:O,'Students (Vertical)'!C:C=E10,'Students (Vertical)'!O:O<>"""")}"&",countifs({filter('Students (Vertical)'!O:O,'Students (Vertical)'!C:C=B10,'Students (Vertical)'!O:O<>"""");filter('Students (Vertical)'!O:O,'Students (Vertical)'!C:C=E10,'Students (Vertical)'!O:O<>"""")},{filter('Students (Vertical)'!O:O,'Students (Vertic"&"al)'!C:C=B10,'Students (Vertical)'!O:O<>"""");filter('Students (Vertical)'!O:O,'Students (Vertical)'!C:C=E10,'Students (Vertical)'!O:O<>"""")})>1))),""No shared courses""),"""")"),"") | J10: =IFERROR(__xludf.DUMMYFUNCTION("if(H10=""Can't be Together"",iferror(join("", "",unique(filter({unique(filter('Students (Vertical)'!O:O,'Students (Vertical)'!C:C=B10,'Students (Vertical)'!O:O<>"""",'Students (Vertical)'!P:P>1));unique(filter('Students (Vertical)'!O:O,'Students (Vertical"&")'!C:C=E10,'Students (Vertical)'!O:O<>"""",'Students (Vertical)'!P:P>1))},countifs({unique(filter('Students (Vertical)'!O:O,'Students (Vertical)'!C:C=B10,'Students (Vertical)'!O:O<>"""",'Students (Vertical)'!P:P>1));unique(filter('Students (Vertical)'!O:O"&",'Students (Vertical)'!C:C=E10,'Students (Vertical)'!O:O<>"""",'Students (Vertical)'!P:P>1))},{unique(filter('Students (Vertical)'!O:O,'Students (Vertical)'!C:C=B10,'Students (Vertical)'!O:O<>"""",'Students (Vertical)'!P:P>1));unique(filter('Students (Ver"&"tical)'!O:O,'Students (Vertical)'!C:C=E10,'Students (Vertical)'!O:O<>"""",'Students (Vertical)'!P:P>1))})>1))),""""),"""")"),"") | K10: =IFERROR(__xludf.DUMMYFUNCTION("iferror(join("", "",unique(filter({filter('Students (Vertical)'!D:D,'Students (Vertical)'!C:C=B10,'Students (Vertical)'!D:D<>"""");filter('Students (Vertical)'!D:D,'Students (Vertical)'!C:C=E10,'Students (Vertical)'!D:D<>"""")},countifs({filter('Students "&"(Vertical)'!D:D,'Students (Vertical)'!C:C=B10,'Students (Vertical)'!D:D<>"""");filter('Students (Vertical)'!D:D,'Students (Vertical)'!C:C=E10,'Students (Vertical)'!D:D<>"""")},{filter('Students (Vertical)'!D:D,'Students (Vertical)'!C:C=B10,'Students (Vert"&"ical)'!D:D<>"""");filter('Students (Vertical)'!D:D,'Students (Vertical)'!C:C=E10,'Students (Vertical)'!D:D<>"""")})>1))),"""")"),"Science 6, English 6, Sociales 6, Spanish 6, PE 6, Art 6S1, Tech 6S2") -> Science 6, English 6, Sociales 6, Spanish 6, PE 6, Art 6S1, Tech 6S2
A11: 10 | B11: MILLAN HUERTAS, EMILIANO | C11: 31157 | D11: 6 | E11: BASTIDAS MEJIA, JUAN JOSE | F11: 31013 | G11: 6 | H11: Must be Together | I11: =IFERROR(__xludf.DUMMYFUNCTION("if(H11=""Must be Together"",iferror(join("", "",unique(filter({filter('Students (Vertical)'!O:O,'Students (Vertical)'!C:C=B11,'Students (Vertical)'!O:O<>"""");filter('Students (Vertical)'!O:O,'Students (Vertical)'!C:C=E11,'Students (Vertical)'!O:O<>"""")}"&",countifs({filter('Students (Vertical)'!O:O,'Students (Vertical)'!C:C=B11,'Students (Vertical)'!O:O<>"""");filter('Students (Vertical)'!O:O,'Students (Vertical)'!C:C=E11,'Students (Vertical)'!O:O<>"""")},{filter('Students (Vertical)'!O:O,'Students (Vertic"&"al)'!C:C=B11,'Students (Vertical)'!O:O<>"""");filter('Students (Vertical)'!O:O,'Students (Vertical)'!C:C=E11,'Students (Vertical)'!O:O<>"""")})>1))),""No shared courses""),"""")"),"Science 6-2, English 6A-1, Sociales 6-4, Spanish 6-3") -> Science 6-2, English 6A-1, Sociales 6-4, Spanish 6-3 | J11: =IFERROR(__xludf.DUMMYFUNCTION("if(H11=""Can't be Together"",iferror(join("", "",unique(filter({unique(filter('Students (Vertical)'!O:O,'Students (Vertical)'!C:C=B11,'Students (Vertical)'!O:O<>"""",'Students (Vertical)'!P:P>1));unique(filter('Students (Vertical)'!O:O,'Students (Vertical"&")'!C:C=E11,'Students (Vertical)'!O:O<>"""",'Students (Vertical)'!P:P>1))},countifs({unique(filter('Students (Vertical)'!O:O,'Students (Vertical)'!C:C=B11,'Students (Vertical)'!O:O<>"""",'Students (Vertical)'!P:P>1));unique(filter('Students (Vertical)'!O:O"&",'Students (Vertical)'!C:C=E11,'Students (Vertical)'!O:O<>"""",'Students (Vertical)'!P:P>1))},{unique(filter('Students (Vertical)'!O:O,'Students (Vertical)'!C:C=B11,'Students (Vertical)'!O:O<>"""",'Students (Vertical)'!P:P>1));unique(filter('Students (Ver"&"tical)'!O:O,'Students (Vertical)'!C:C=E11,'Students (Vertical)'!O:O<>"""",'Students (Vertical)'!P:P>1))})>1))),""""),"""")"),"") | K11: =IFERROR(__xludf.DUMMYFUNCTION("iferror(join("", "",unique(filter({filter('Students (Vertical)'!D:D,'Students (Vertical)'!C:C=B11,'Students (Vertical)'!D:D<>"""");filter('Students (Vertical)'!D:D,'Students (Vertical)'!C:C=E11,'Students (Vertical)'!D:D<>"""")},countifs({filter('Students "&"(Vertical)'!D:D,'Students (Vertical)'!C:C=B11,'Students (Vertical)'!D:D<>"""");filter('Students (Vertical)'!D:D,'Students (Vertical)'!C:C=E11,'Students (Vertical)'!D:D<>"""")},{filter('Students (Vertical)'!D:D,'Students (Vertical)'!C:C=B11,'Students (Vert"&"ical)'!D:D<>"""");filter('Students (Vertical)'!D:D,'Students (Vertical)'!C:C=E11,'Students (Vertical)'!D:D<>"""")})>1))),"""")"),"Science 6, Math 6, English 6A, Sociales 6, Spanish 6, PE 6") -> Science 6, Math 6, English 6A, Sociales 6, Spanish 6, PE 6
A12: 11 | B12: MILLAN HUERTAS, EMILIANO | C12: 31157 | D12: 6 | E12: BOTERO BOTERO, AMALIA | F12: 31019 | G12: 6 | H12: Can't be Together | I12: =IFERROR(__xludf.DUMMYFUNCTION("if(H12=""Must be Together"",iferror(join("", "",unique(filter({filter('Students (Vertical)'!O:O,'Students (Vertical)'!C:C=B12,'Students (Vertical)'!O:O<>"""");filter('Students (Vertical)'!O:O,'Students (Vertical)'!C:C=E12,'Students (Vertical)'!O:O<>"""")}"&",countifs({filter('Students (Vertical)'!O:O,'Students (Vertical)'!C:C=B12,'Students (Vertical)'!O:O<>"""");filter('Students (Vertical)'!O:O,'Students (Vertical)'!C:C=E12,'Students (Vertical)'!O:O<>"""")},{filter('Students (Vertical)'!O:O,'Students (Vertic"&"al)'!C:C=B12,'Students (Vertical)'!O:O<>"""");filter('Students (Vertical)'!O:O,'Students (Vertical)'!C:C=E12,'Students (Vertical)'!O:O<>"""")})>1))),""No shared courses""),"""")"),"") | J12: =IFERROR(__xludf.DUMMYFUNCTION("if(H12=""Can't be Together"",iferror(join("", "",unique(filter({unique(filter('Students (Vertical)'!O:O,'Students (Vertical)'!C:C=B12,'Students (Vertical)'!O:O<>"""",'Students (Vertical)'!P:P>1));unique(filter('Students (Vertical)'!O:O,'Students (Vertical"&")'!C:C=E12,'Students (Vertical)'!O:O<>"""",'Students (Vertical)'!P:P>1))},countifs({unique(filter('Students (Vertical)'!O:O,'Students (Vertical)'!C:C=B12,'Students (Vertical)'!O:O<>"""",'Students (Vertical)'!P:P>1));unique(filter('Students (Vertical)'!O:O"&",'Students (Vertical)'!C:C=E12,'Students (Vertical)'!O:O<>"""",'Students (Vertical)'!P:P>1))},{unique(filter('Students (Vertical)'!O:O,'Students (Vertical)'!C:C=B12,'Students (Vertical)'!O:O<>"""",'Students (Vertical)'!P:P>1));unique(filter('Students (Ver"&"tical)'!O:O,'Students (Vertical)'!C:C=E12,'Students (Vertical)'!O:O<>"""",'Students (Vertical)'!P:P>1))})>1))),""""),"""")"),"") | K12: =IFERROR(__xludf.DUMMYFUNCTION("iferror(join("", "",unique(filter({filter('Students (Vertical)'!D:D,'Students (Vertical)'!C:C=B12,'Students (Vertical)'!D:D<>"""");filter('Students (Vertical)'!D:D,'Students (Vertical)'!C:C=E12,'Students (Vertical)'!D:D<>"""")},countifs({filter('Students "&"(Vertical)'!D:D,'Students (Vertical)'!C:C=B12,'Students (Vertical)'!D:D<>"""");filter('Students (Vertical)'!D:D,'Students (Vertical)'!C:C=E12,'Students (Vertical)'!D:D<>"""")},{filter('Students (Vertical)'!D:D,'Students (Vertical)'!C:C=B12,'Students (Vert"&"ical)'!D:D<>"""");filter('Students (Vertical)'!D:D,'Students (Vertical)'!C:C=E12,'Students (Vertical)'!D:D<>"""")})>1))),"""")"),"Science 6, Math 6, Sociales 6, Spanish 6, PE 6, Art 6S1, Tech 6S2") -> Science 6, Math 6, Sociales 6, Spanish 6, PE 6, Art 6S1, Tech 6S2
A13: 12 | B13: MILLAN HUERTAS, EMILIANO | C13: 31157 | D13: 6 | E13: PELAEZ BOTERO, AMELIA | F13: 31088 | G13: 6 | H13: Can't be Together | I13: =IFERROR(__xludf.DUMMYFUNCTION("if(H13=""Must be Together"",iferror(join("", "",unique(filter({filter('Students (Vertical)'!O:O,'Students (Vertical)'!C:C=B13,'Students (Vertical)'!O:O<>"""");filter('Students (Vertical)'!O:O,'Students (Vertical)'!C:C=E13,'Students (Vertical)'!O:O<>"""")}"&",countifs({filter('Students (Vertical)'!O:O,'Students (Vertical)'!C:C=B13,'Students (Vertical)'!O:O<>"""");filter('Students (Vertical)'!O:O,'Students (Vertical)'!C:C=E13,'Students (Vertical)'!O:O<>"""")},{filter('Students (Vertical)'!O:O,'Students (Vertic"&"al)'!C:C=B13,'Students (Vertical)'!O:O<>"""");filter('Students (Vertical)'!O:O,'Students (Vertical)'!C:C=E13,'Students (Vertical)'!O:O<>"""")})>1))),""No shared courses""),"""")"),"") | J13: =IFERROR(__xludf.DUMMYFUNCTION("if(H13=""Can't be Together"",iferror(join("", "",unique(filter({unique(filter('Students (Vertical)'!O:O,'Students (Vertical)'!C:C=B13,'Students (Vertical)'!O:O<>"""",'Students (Vertical)'!P:P>1));unique(filter('Students (Vertical)'!O:O,'Students (Vertical"&")'!C:C=E13,'Students (Vertical)'!O:O<>"""",'Students (Vertical)'!P:P>1))},countifs({unique(filter('Students (Vertical)'!O:O,'Students (Vertical)'!C:C=B13,'Students (Vertical)'!O:O<>"""",'Students (Vertical)'!P:P>1));unique(filter('Students (Vertical)'!O:O"&",'Students (Vertical)'!C:C=E13,'Students (Vertical)'!O:O<>"""",'Students (Vertical)'!P:P>1))},{unique(filter('Students (Vertical)'!O:O,'Students (Vertical)'!C:C=B13,'Students (Vertical)'!O:O<>"""",'Students (Vertical)'!P:P>1));unique(filter('Students (Ver"&"tical)'!O:O,'Students (Vertical)'!C:C=E13,'Students (Vertical)'!O:O<>"""",'Students (Vertical)'!P:P>1))})>1))),""""),"""")"),"") | K13: =IFERROR(__xludf.DUMMYFUNCTION("iferror(join("", "",unique(filter({filter('Students (Vertical)'!D:D,'Students (Vertical)'!C:C=B13,'Students (Vertical)'!D:D<>"""");filter('Students (Vertical)'!D:D,'Students (Vertical)'!C:C=E13,'Students (Vertical)'!D:D<>"""")},countifs({filter('Students "&"(Vertical)'!D:D,'Students (Vertical)'!C:C=B13,'Students (Vertical)'!D:D<>"""");filter('Students (Vertical)'!D:D,'Students (Vertical)'!C:C=E13,'Students (Vertical)'!D:D<>"""")},{filter('Students (Vertical)'!D:D,'Students (Vertical)'!C:C=B13,'Students (Vert"&"ical)'!D:D<>"""");filter('Students (Vertical)'!D:D,'Students (Vertical)'!C:C=E13,'Students (Vertical)'!D:D<>"""")})>1))),"""")"),"Science 6, Math 6, Sociales 6, Spanish 6, PE 6, Art 6S1, Tech 6S2") -> Science 6, Math 6, Sociales 6, Spanish 6, PE 6, Art 6S1, Tech 6S2
A14: 13 | B14: MILLAN HUERTAS, EMILIANO | C14: 31157 | D14: 6 | E14: ALVAREZ RIVERA, SALVADOR | F14: 31004 | G14: 6 | H14: Can't be Together | I14: =IFERROR(__xludf.DUMMYFUNCTION("if(H14=""Must be Together"",iferror(join("", "",unique(filter({filter('Students (Vertical)'!O:O,'Students (Vertical)'!C:C=B14,'Students (Vertical)'!O:O<>"""");filter('Students (Vertical)'!O:O,'Students (Vertical)'!C:C=E14,'Students (Vertical)'!O:O<>"""")}"&",countifs({filter('Students (Vertical)'!O:O,'Students (Vertical)'!C:C=B14,'Students (Vertical)'!O:O<>"""");filter('Students (Vertical)'!O:O,'Students (Vertical)'!C:C=E14,'Students (Vertical)'!O:O<>"""")},{filter('Students (Vertical)'!O:O,'Students (Vertic"&"al)'!C:C=B14,'Students (Vertical)'!O:O<>"""");filter('Students (Vertical)'!O:O,'Students (Vertical)'!C:C=E14,'Students (Vertical)'!O:O<>"""")})>1))),""No shared courses""),"""")"),"") | J14: =IFERROR(__xludf.DUMMYFUNCTION("if(H14=""Can't be Together"",iferror(join("", "",unique(filter({unique(filter('Students (Vertical)'!O:O,'Students (Vertical)'!C:C=B14,'Students (Vertical)'!O:O<>"""",'Students (Vertical)'!P:P>1));unique(filter('Students (Vertical)'!O:O,'Students (Vertical"&")'!C:C=E14,'Students (Vertical)'!O:O<>"""",'Students (Vertical)'!P:P>1))},countifs({unique(filter('Students (Vertical)'!O:O,'Students (Vertical)'!C:C=B14,'Students (Vertical)'!O:O<>"""",'Students (Vertical)'!P:P>1));unique(filter('Students (Vertical)'!O:O"&",'Students (Vertical)'!C:C=E14,'Students (Vertical)'!O:O<>"""",'Students (Vertical)'!P:P>1))},{unique(filter('Students (Vertical)'!O:O,'Students (Vertical)'!C:C=B14,'Students (Vertical)'!O:O<>"""",'Students (Vertical)'!P:P>1));unique(filter('Students (Ver"&"tical)'!O:O,'Students (Vertical)'!C:C=E14,'Students (Vertical)'!O:O<>"""",'Students (Vertical)'!P:P>1))})>1))),""""),"""")"),"") | K14: =IFERROR(__xludf.DUMMYFUNCTION("iferror(join("", "",unique(filter({filter('Students (Vertical)'!D:D,'Students (Vertical)'!C:C=B14,'Students (Vertical)'!D:D<>"""");filter('Students (Vertical)'!D:D,'Students (Vertical)'!C:C=E14,'Students (Vertical)'!D:D<>"""")},countifs({filter('Students "&"(Vertical)'!D:D,'Students (Vertical)'!C:C=B14,'Students (Vertical)'!D:D<>"""");filter('Students (Vertical)'!D:D,'Students (Vertical)'!C:C=E14,'Students (Vertical)'!D:D<>"""")},{filter('Students (Vertical)'!D:D,'Students (Vertical)'!C:C=B14,'Students (Vert"&"ical)'!D:D<>"""");filter('Students (Vertical)'!D:D,'Students (Vertical)'!C:C=E14,'Students (Vertical)'!D:D<>"""")})>1))),"""")"),"Science 6, Math 6, Sociales 6, Spanish 6, PE 6") -> Science 6, Math 6, Sociales 6, Spanish 6, PE 6
A15: 14 | B15: MILLAN HUERTAS, EMILIANO | C15: 31157 | D15: 6 | E15: DE LOS RIOS AGUDELO, MATIAS | F15: 31031 | G15: 6 | H15: Must be Together | I15: =IFERROR(__xludf.DUMMYFUNCTION("if(H15=""Must be Together"",iferror(join("", "",unique(filter({filter('Students (Vertical)'!O:O,'Students (Vertical)'!C:C=B15,'Students (Vertical)'!O:O<>"""");filter('Students (Vertical)'!O:O,'Students (Vertical)'!C:C=E15,'Students (Vertical)'!O:O<>"""")}"&",countifs({filter('Students (Vertical)'!O:O,'Students (Vertical)'!C:C=B15,'Students (Vertical)'!O:O<>"""");filter('Students (Vertical)'!O:O,'Students (Vertical)'!C:C=E15,'Students (Vertical)'!O:O<>"""")},{filter('Students (Vertical)'!O:O,'Students (Vertic"&"al)'!C:C=B15,'Students (Vertical)'!O:O<>"""");filter('Students (Vertical)'!O:O,'Students (Vertical)'!C:C=E15,'Students (Vertical)'!O:O<>"""")})>1))),""No shared courses""),"""")"),"Science 6-2, English 6A-1, Sociales 6-4, Spanish 6-3") -> Science 6-2, English 6A-1, Sociales 6-4, Spanish 6-3 | J15: =IFERROR(__xludf.DUMMYFUNCTION("if(H15=""Can't be Together"",iferror(join("", "",unique(filter({unique(filter('Students (Vertical)'!O:O,'Students (Vertical)'!C:C=B15,'Students (Vertical)'!O:O<>"""",'Students (Vertical)'!P:P>1));unique(filter('Students (Vertical)'!O:O,'Students (Vertical"&")'!C:C=E15,'Students (Vertical)'!O:O<>"""",'Students (Vertical)'!P:P>1))},countifs({unique(filter('Students (Vertical)'!O:O,'Students (Vertical)'!C:C=B15,'Students (Vertical)'!O:O<>"""",'Students (Vertical)'!P:P>1));unique(filter('Students (Vertical)'!O:O"&",'Students (Vertical)'!C:C=E15,'Students (Vertical)'!O:O<>"""",'Students (Vertical)'!P:P>1))},{unique(filter('Students (Vertical)'!O:O,'Students (Vertical)'!C:C=B15,'Students (Vertical)'!O:O<>"""",'Students (Vertical)'!P:P>1));unique(filter('Students (Ver"&"tical)'!O:O,'Students (Vertical)'!C:C=E15,'Students (Vertical)'!O:O<>"""",'Students (Vertical)'!P:P>1))})>1))),""""),"""")"),"") | K15: =IFERROR(__xludf.DUMMYFUNCTION("iferror(join("", "",unique(filter({filter('Students (Vertical)'!D:D,'Students (Vertical)'!C:C=B15,'Students (Vertical)'!D:D<>"""");filter('Students (Vertical)'!D:D,'Students (Vertical)'!C:C=E15,'Students (Vertical)'!D:D<>"""")},countifs({filter('Students "&"(Vertical)'!D:D,'Students (Vertical)'!C:C=B15,'Students (Vertical)'!D:D<>"""");filter('Students (Vertical)'!D:D,'Students (Vertical)'!C:C=E15,'Students (Vertical)'!D:D<>"""")},{filter('Students (Vertical)'!D:D,'Students (Vertical)'!C:C=B15,'Students (Vert"&"ical)'!D:D<>"""");filter('Students (Vertical)'!D:D,'Students (Vertical)'!C:C=E15,'Students (Vertical)'!D:D<>"""")})>1))),"""")"),"Science 6, Math 6, English 6A, Sociales 6, Spanish 6, PE 6") -> Science 6, Math 6, English 6A, Sociales 6, Spanish 6, PE 6
A16: 15 | B16: MATALLANA TOBON, ROSARIO | C16: 31066 | D16: 6 | E16: PUYO TORO, ELENA | F16: 31097 | G16: 6 | H16: Can't be Together | I16: =IFERROR(__xludf.DUMMYFUNCTION("if(H16=""Must be Together"",iferror(join("", "",unique(filter({filter('Students (Vertical)'!O:O,'Students (Vertical)'!C:C=B16,'Students (Vertical)'!O:O<>"""");filter('Students (Vertical)'!O:O,'Students (Vertical)'!C:C=E16,'Students (Vertical)'!O:O<>"""")}"&",countifs({filter('Students (Vertical)'!O:O,'Students (Vertical)'!C:C=B16,'Students (Vertical)'!O:O<>"""");filter('Students (Vertical)'!O:O,'Students (Vertical)'!C:C=E16,'Students (Vertical)'!O:O<>"""")},{filter('Students (Vertical)'!O:O,'Students (Vertic"&"al)'!C:C=B16,'Students (Vertical)'!O:O<>"""");filter('Students (Vertical)'!O:O,'Students (Vertical)'!C:C=E16,'Students (Vertical)'!O:O<>"""")})>1))),""No shared courses""),"""")"),"") | J16: =IFERROR(__xludf.DUMMYFUNCTION("if(H16=""Can't be Together"",iferror(join("", "",unique(filter({unique(filter('Students (Vertical)'!O:O,'Students (Vertical)'!C:C=B16,'Students (Vertical)'!O:O<>"""",'Students (Vertical)'!P:P>1));unique(filter('Students (Vertical)'!O:O,'Students (Vertical"&")'!C:C=E16,'Students (Vertical)'!O:O<>"""",'Students (Vertical)'!P:P>1))},countifs({unique(filter('Students (Vertical)'!O:O,'Students (Vertical)'!C:C=B16,'Students (Vertical)'!O:O<>"""",'Students (Vertical)'!P:P>1));unique(filter('Students (Vertical)'!O:O"&",'Students (Vertical)'!C:C=E16,'Students (Vertical)'!O:O<>"""",'Students (Vertical)'!P:P>1))},{unique(filter('Students (Vertical)'!O:O,'Students (Vertical)'!C:C=B16,'Students (Vertical)'!O:O<>"""",'Students (Vertical)'!P:P>1));unique(filter('Students (Ver"&"tical)'!O:O,'Students (Vertical)'!C:C=E16,'Students (Vertical)'!O:O<>"""",'Students (Vertical)'!P:P>1))})>1))),""""),"""")"),"") | K16: =IFERROR(__xludf.DUMMYFUNCTION("iferror(join("", "",unique(filter({filter('Students (Vertical)'!D:D,'Students (Vertical)'!C:C=B16,'Students (Vertical)'!D:D<>"""");filter('Students (Vertical)'!D:D,'Students (Vertical)'!C:C=E16,'Students (Vertical)'!D:D<>"""")},countifs({filter('Students "&"(Vertical)'!D:D,'Students (Vertical)'!C:C=B16,'Students (Vertical)'!D:D<>"""");filter('Students (Vertical)'!D:D,'Students (Vertical)'!C:C=E16,'Students (Vertical)'!D:D<>"""")},{filter('Students (Vertical)'!D:D,'Students (Vertical)'!C:C=B16,'Students (Vert"&"ical)'!D:D<>"""");filter('Students (Vertical)'!D:D,'Students (Vertical)'!C:C=E16,'Students (Vertical)'!D:D<>"""")})>1))),"""")"),"Science 6, Math 6, English 6, Sociales 6, Spanish 6, PE 6") -> Science 6, Math 6, English 6, Sociales 6, Spanish 6, PE 6
